Workbook

Sheet Setup
A1: SKU MASTER DATA
A3: SKU # | B3: SKU Name | C3: Brand | D3: Units/Ctn | E3: Price/Pack (Rs)
A4: 1 | B4: Kite Rs 10 | C4: Kite Glow | D4: 144 | E4: 8.68
A5: 2 | B5: Kite Rs 20 | C5: Kite Glow | D5: 96 | E5: 16.28
A6: 3 | B6: Kite Rs 50 | C6: Kite Glow | D6: 48 | E6: 44.64
A7: 4 | B7: Kite Rs 99 | C7: Kite Glow | D7: 24 | E7: 86.65
A8: 5 | B8: Kite 0.5kg | C8: Kite Glow | D8: 24 | E8: 148.8
A9: 6 | B9: Kite 1kg | C9: Kite Glow | D9: 12 | E9: 279
A10: 7 | B10: Kite 2kg | C10: Kite Glow | D10: 6
A11: 8 | B11: Burq Rs 10 | C11: Burq Action | D11: 204
A12: 9 | B12: Burq Rs 20 | C12: Burq Action | D12: 96
A13: 10 | B13: Burq Rs 50 | C13: Burq Action | D13: 48
A14: 11 | B14: Burq Rs 99 | C14: Burq Action | D14: 24
A15: 12 | B15: Burq 1kg | C15: Burq Action | D15: 12
A16: 13 | B16: Burq 2.3kg | C16: Burq Action | D16: 6
A17: 14 | B17: Vero 5kg | C17: Vero | D17: 4
A18: 15 | B18: Vero 20kg | C18: Vero | D18: 1
A19: 16 | B19: Regular | C19: DWB | D19: 48
A20: 17 | B20: Large | C20: DWB | D20: 36
A21: 18 | B21: Long Bar | C21: DWB | D21: 36
... A37: 34 | B37: Tanga (C) | C37: Match | D37: 10

Sheet Primary Sales Entry
A1: PRIMARY SALES ENTRY (Multiple entries allowed)
A2: Enter multiple primary sales transactions - Date, SKU, Cartons
A4: Date | B4: SKU # | C4: SKU Name | D4: Units/Ctn | E4: Primary Sales (Ctns) | F4: Amount (Rs)
F5: =E5*VLOOKUP(B5,Setup!A:E,5,FALSE)
F6: =E6*VLOOKUP(B6,Setup!A:E,5,FALSE)
F7: =E7*VLOOKUP(B7,Setup!A:E,5,FALSE)
F8: =E8*VLOOKUP(B8,Setup!A:E,5,FALSE)
F9: =E9*VLOOKUP(B9,Setup!A:E,5,FALSE)
F10: =E10*VLOOKUP(B10,Setup!A:E,5,FALSE)
F11: =E11*VLOOKUP(B11,Setup!A:E,5,FALSE)
F12: =E12*VLOOKUP(B12,Setup!A:E,5,FALSE)
F13: =E13*VLOOKUP(B13,Setup!A:E,5,FALSE)
F14: =E14*VLOOKUP(B14,Setup!A:E,5,FALSE)
F15: =E15*VLOOKUP(B15,Setup!A:E,5,FALSE)
F16: =E16*VLOOKUP(B16,Setup!A:E,5,FALSE)
... F54: =E54*VLOOKUP(B54,Setup!A:E,5,FALSE)

Sheet Day 01
A1: DAILY SALES & EXPENSES - DAY 1
A3: DAILY SALES ENTRY (Packs)
A5: SKU # | B5: SKU Name | C5: Packs Sold | D5: Units/Ctn | E5: Ctns | F5: Packs | G5: Rs/Pack | H5: Total Rs
A6: 1 | B6: Kite Rs 10 | D6: 144 | E6: =INT(C6/D6) | F6: =C6-(E6*D6) | H6: =C6*G6
A7: 2 | B7: Kite Rs 20 | D7: 96 | E7: =INT(C7/D7) | F7: =C7-(E7*D7) | H7: =C7*G7
A8: 3 | B8: Kite Rs 50 | D8: 48 | E8: =INT(C8/D8) | F8: =C8-(E8*D8) | H8: =C8*G8
A9: 4 | B9: Kite Rs 99 | D9: 24 | E9: =INT(C9/D9) | F9: =C9-(E9*D9) | H9: =C9*G9
A10: 5 | B10: Kite 0.5kg | D10: 24 | E10: =INT(C10/D10) | F10: =C10-(E10*D10) | H10: =C10*G10
A11: 6 | B11: Kite 1kg | D11: 12 | E11: =INT(C11/D11) | F11: =C11-(E11*D11) | H11: =C11*G11
A12: 7 | B12: Kite 2kg | D12: 6 | E12: =INT(C12/D12) | F12: =C12-(E12*D12) | H12: =C12*G12
A13: 8 | B13: Burq Rs 10 | D13: 204 | E13: =INT(C13/D13) | F13: =C13-(E13*D13) | H13: =C13*G13
A14: 9 | B14: Burq Rs 20 | D14: 96 | E14: =INT(C14/D14) | F14: =C14-(E14*D14) | H14: =C14*G14
A15: 10 | B15: Burq Rs 50 | D15: 48 | E15: =INT(C15/D15) | F15: =C15-(E15*D15) | H15: =C15*G15
A16: 11 | B16: Burq Rs 99 | D16: 24 | E16: =INT(C16/D16) | F16: =C16-(E16*D16) | H16: =C16*G16
A17: 12 | B17: Burq 1kg | D17: 12 | E17: =INT(C17/D17) | F17: =C17-(E17*D17) | H17: =C17*G17
... A39: 34 | B39: Tanga (C) | D39: 10 | E39: =INT(C39/D39) | F39: =C39-(E39*D39) | H39: =C39*G39
A40: TOTALS | E40: =SUM(E6:E39) | H40: =SUM(H6:H39)
A43: DAILY EXPENSES
A45: Category | B45: Amount (Rs)
A46: Labor | B46: 0
A47: Transport | B47: 0
A48: Utilities | B48: 0
A49: Packaging | B49: 0
A50: Other | B50: 0
A51: Total Expenses | B51: =SUM(B46:B50)

Sheet Day 02
A1: DAILY SALES & EXPENSES - DAY 2
A3: DAILY SALES ENTRY (Packs)
A5: SKU # | B5: SKU Name | C5: Packs Sold | D5: Units/Ctn | E5: Ctns | F5: Packs | G5: Rs/Pack | H5: Total Rs
A6: 1 | B6: Kite Rs 10 | D6: 144 | E6: =INT(C6/D6) | F6: =C6-(E6*D6) | H6: =C6*G6
A7: 2 | B7: Kite Rs 20 | D7: 96 | E7: =INT(C7/D7) | F7: =C7-(E7*D7) | H7: =C7*G7
A8: 3 | B8: Kite Rs 50 | D8: 48 | E8: =INT(C8/D8) | F8: =C8-(E8*D8) | H8: =C8*G8
A9: 4 | B9: Kite Rs 99 | D9: 24 | E9: =INT(C9/D9) | F9: =C9-(E9*D9) | H9: =C9*G9
A10: 5 | B10: Kite 0.5kg | D10: 24 | E10: =INT(C10/D10) | F10: =C10-(E10*D10) | H10: =C10*G10
A11: 6 | B11: Kite 1kg | D11: 12 | E11: =INT(C11/D11) | F11: =C11-(E11*D11) | H11: =C11*G11
A12: 7 | B12: Kite 2kg | D12: 6 | E12: =INT(C12/D12) | F12: =C12-(E12*D12) | H12: =C12*G12
A13: 8 | B13: Burq Rs 10 | D13: 204 | E13: =INT(C13/D13) | F13: =C13-(E13*D13) | H13: =C13*G13
A14: 9 | B14: Burq Rs 20 | D14: 96 | E14: =INT(C14/D14) | F14: =C14-(E14*D14) | H14: =C14*G14
A15: 10 | B15: Burq Rs 50 | D15: 48 | E15: =INT(C15/D15) | F15: =C15-(E15*D15) | H15: =C15*G15
A16: 11 | B16: Burq Rs 99 | D16: 24 | E16: =INT(C16/D16) | F16: =C16-(E16*D16) | H16: =C16*G16
A17: 12 | B17: Burq 1kg | D17: 12 | E17: =INT(C17/D17) | F17: =C17-(E17*D17) | H17: =C17*G17
... A39: 34 | B39: Tanga (C) | D39: 10 | E39: =INT(C39/D39) | F39: =C39-(E39*D39) | H39: =C39*G39
A40: TOTALS | E40: =SUM(E6:E39) | H40: =SUM(H6:H39)
A43: DAILY EXPENSES
A45: Category | B45: Amount (Rs)
A46: Labor | B46: 0
A47: Transport | B47: 0
A48: Utilities | B48: 0
A49: Packaging | B49: 0
A50: Other | B50: 0
A51: Total Expenses | B51: =SUM(B46:B50)

Sheet Day 03
A1: DAILY SALES & EXPENSES - DAY 3
A3: DAILY SALES ENTRY (Packs)
A5: SKU # | B5: SKU Name | C5: Packs Sold | D5: Units/Ctn | E5: Ctns | F5: Packs | G5: Rs/Pack | H5: Total Rs
A6: 1 | B6: Kite Rs 10 | D6: 144 | E6: =INT(C6/D6) | F6: =C6-(E6*D6) | H6: =C6*G6
A7: 2 | B7: Kite Rs 20 | D7: 96 | E7: =INT(C7/D7) | F7: =C7-(E7*D7) | H7: =C7*G7
A8: 3 | B8: Kite Rs 50 | D8: 48 | E8: =INT(C8/D8) | F8: =C8-(E8*D8) | H8: =C8*G8
A9: 4 | B9: Kite Rs 99 | D9: 24 | E9: =INT(C9/D9) | F9: =C9-(E9*D9) | H9: =C9*G9
A10: 5 | B10: Kite 0.5kg | D10: 24 | E10: =INT(C10/D10) | F10: =C10-(E10*D10) | H10: =C10*G10
A11: 6 | B11: Kite 1kg | D11: 12 | E11: =INT(C11/D11) | F11: =C11-(E11*D11) | H11: =C11*G11
A12: 7 | B12: Kite 2kg | D12: 6 | E12: =INT(C12/D12) | F12: =C12-(E12*D12) | H12: =C12*G12
A13: 8 | B13: Burq Rs 10 | D13: 204 | E13: =INT(C13/D13) | F13: =C13-(E13*D13) | H13: =C13*G13
A14: 9 | B14: Burq Rs 20 | D14: 96 | E14: =INT(C14/D14) | F14: =C14-(E14*D14) | H14: =C14*G14
A15: 10 | B15: Burq Rs 50 | D15: 48 | E15: =INT(C15/D15) | F15: =C15-(E15*D15) | H15: =C15*G15
A16: 11 | B16: Burq Rs 99 | D16: 24 | E16: =INT(C16/D16) | F16: =C16-(E16*D16) | H16: =C16*G16
A17: 12 | B17: Burq 1kg | D17: 12 | E17: =INT(C17/D17) | F17: =C17-(E17*D17) | H17: =C17*G17
... A39: 34 | B39: Tanga (C) | D39: 10 | E39: =INT(C39/D39) | F39: =C39-(E39*D39) | H39: =C39*G39
A40: TOTALS | E40: =SUM(E6:E39) | H40: =SUM(H6:H39)
A43: DAILY EXPENSES
A45: Category | B45: Amount (Rs)
A46: Labor | B46: 0
A47: Transport | B47: 0
A48: Utilities | B48: 0
A49: Packaging | B49: 0
A50: Other | B50: 0
A51: Total Expenses | B51: =SUM(B46:B50)

Sheet Day 04
A1: DAILY SALES & EXPENSES - DAY 4
A3: DAILY SALES ENTRY (Packs)
A5: SKU # | B5: SKU Name | C5: Packs Sold | D5: Units/Ctn | E5: Ctns | F5: Packs | G5: Rs/Pack | H5: Total Rs
A6: 1 | B6: Kite Rs 10 | D6: 144 | E6: =INT(C6/D6) | F6: =C6-(E6*D6) | H6: =C6*G6
A7: 2 | B7: Kite Rs 20 | D7: 96 | E7: =INT(C7/D7) | F7: =C7-(E7*D7) | H7: =C7*G7
A8: 3 | B8: Kite Rs 50 | D8: 48 | E8: =INT(C8/D8) | F8: =C8-(E8*D8) | H8: =C8*G8
A9: 4 | B9: Kite Rs 99 | D9: 24 | E9: =INT(C9/D9) | F9: =C9-(E9*D9) | H9: =C9*G9
A10: 5 | B10: Kite 0.5kg | D10: 24 | E10: =INT(C10/D10) | F10: =C10-(E10*D10) | H10: =C10*G10
A11: 6 | B11: Kite 1kg | D11: 12 | E11: =INT(C11/D11) | F11: =C11-(E11*D11) | H11: =C11*G11
A12: 7 | B12: Kite 2kg | D12: 6 | E12: =INT(C12/D12) | F12: =C12-(E12*D12) | H12: =C12*G12
A13: 8 | B13: Burq Rs 10 | D13: 204 | E13: =INT(C13/D13) | F13: =C13-(E13*D13) | H13: =C13*G13
A14: 9 | B14: Burq Rs 20 | D14: 96 | E14: =INT(C14/D14) | F14: =C14-(E14*D14) | H14: =C14*G14
A15: 10 | B15: Burq Rs 50 | D15: 48 | E15: =INT(C15/D15) | F15: =C15-(E15*D15) | H15: =C15*G15
A16: 11 | B16: Burq Rs 99 | D16: 24 | E16: =INT(C16/D16) | F16: =C16-(E16*D16) | H16: =C16*G16
A17: 12 | B17: Burq 1kg | D17: 12 | E17: =INT(C17/D17) | F17: =C17-(E17*D17) | H17: =C17*G17
... A39: 34 | B39: Tanga (C) | D39: 10 | E39: =INT(C39/D39) | F39: =C39-(E39*D39) | H39: =C39*G39
A40: TOTALS | E40: =SUM(E6:E39) | H40: =SUM(H6:H39)
A43: DAILY EXPENSES
A45: Category | B45: Amount (Rs)
A46: Labor | B46: 0
A47: Transport | B47: 0
A48: Utilities | B48: 0
A49: Packaging | B49: 0
A50: Other | B50: 0
A51: Total Expenses | B51: =SUM(B46:B50)

Sheet Day 05
A1: DAILY SALES & EXPENSES - DAY 5
A3: DAILY SALES ENTRY (Packs)
A5: SKU # | B5: SKU Name | C5: Packs Sold | D5: Units/Ctn | E5: Ctns | F5: Packs | G5: Rs/Pack | H5: Total Rs
A6: 1 | B6: Kite Rs 10 | D6: 144 | E6: =INT(C6/D6) | F6: =C6-(E6*D6) | H6: =C6*G6
A7: 2 | B7: Kite Rs 20 | D7: 96 | E7: =INT(C7/D7) | F7: =C7-(E7*D7) | H7: =C7*G7
A8: 3 | B8: Kite Rs 50 | D8: 48 | E8: =INT(C8/D8) | F8: =C8-(E8*D8) | H8: =C8*G8
A9: 4 | B9: Kite Rs 99 | D9: 24 | E9: =INT(C9/D9) | F9: =C9-(E9*D9) | H9: =C9*G9
A10: 5 | B10: Kite 0.5kg | D10: 24 | E10: =INT(C10/D10) | F10: =C10-(E10*D10) | H10: =C10*G10
A11: 6 | B11: Kite 1kg | D11: 12 | E11: =INT(C11/D11) | F11: =C11-(E11*D11) | H11: =C11*G11
A12: 7 | B12: Kite 2kg | D12: 6 | E12: =INT(C12/D12) | F12: =C12-(E12*D12) | H12: =C12*G12
A13: 8 | B13: Burq Rs 10 | D13: 204 | E13: =INT(C13/D13) | F13: =C13-(E13*D13) | H13: =C13*G13
A14: 9 | B14: Burq Rs 20 | D14: 96 | E14: =INT(C14/D14) | F14: =C14-(E14*D14) | H14: =C14*G14
A15: 10 | B15: Burq Rs 50 | D15: 48 | E15: =INT(C15/D15) | F15: =C15-(E15*D15) | H15: =C15*G15
A16: 11 | B16: Burq Rs 99 | D16: 24 | E16: =INT(C16/D16) | F16: =C16-(E16*D16) | H16: =C16*G16
A17: 12 | B17: Burq 1kg | D17: 12 | E17: =INT(C17/D17) | F17: =C17-(E17*D17) | H17: =C17*G17
... A39: 34 | B39: Tanga (C) | D39: 10 | E39: =INT(C39/D39) | F39: =C39-(E39*D39) | H39: =C39*G39
A40: TOTALS | E40: =SUM(E6:E39) | H40: =SUM(H6:H39)
A43: DAILY EXPENSES
A45: Category | B45: Amount (Rs)
A46: Labor | B46: 0
A47: Transport | B47: 0
A48: Utilities | B48: 0
A49: Packaging | B49: 0
A50: Other | B50: 0
A51: Total Expenses | B51: =SUM(B46:B50)

Sheet Day 06
A1: DAILY SALES & EXPENSES - DAY 6
A3: DAILY SALES ENTRY (Packs)
A5: SKU # | B5: SKU Name | C5: Packs Sold | D5: Units/Ctn | E5: Ctns | F5: Packs | G5: Rs/Pack | H5: Total Rs
A6: 1 | B6: Kite Rs 10 | D6: 144 | E6: =INT(C6/D6) | F6: =C6-(E6*D6) | H6: =C6*G6
A7: 2 | B7: Kite Rs 20 | D7: 96 | E7: =INT(C7/D7) | F7: =C7-(E7*D7) | H7: =C7*G7
A8: 3 | B8: Kite Rs 50 | D8: 48 | E8: =INT(C8/D8) | F8: =C8-(E8*D8) | H8: =C8*G8
A9: 4 | B9: Kite Rs 99 | D9: 24 | E9: =INT(C9/D9) | F9: =C9-(E9*D9) | H9: =C9*G9
A10: 5 | B10: Kite 0.5kg | D10: 24 | E10: =INT(C10/D10) | F10: =C10-(E10*D10) | H10: =C10*G10
A11: 6 | B11: Kite 1kg | D11: 12 | E11: =INT(C11/D11) | F11: =C11-(E11*D11) | H11: =C11*G11
A12: 7 | B12: Kite 2kg | D12: 6 | E12: =INT(C12/D12) | F12: =C12-(E12*D12) | H12: =C12*G12
A13: 8 | B13: Burq Rs 10 | D13: 204 | E13: =INT(C13/D13) | F13: =C13-(E13*D13) | H13: =C13*G13
A14: 9 | B14: Burq Rs 20 | D14: 96 | E14: =INT(C14/D14) | F14: =C14-(E14*D14) | H14: =C14*G14
A15: 10 | B15: Burq Rs 50 | D15: 48 | E15: =INT(C15/D15) | F15: =C15-(E15*D15) | H15: =C15*G15
A16: 11 | B16: Burq Rs 99 | D16: 24 | E16: =INT(C16/D16) | F16: =C16-(E16*D16) | H16: =C16*G16
A17: 12 | B17: Burq 1kg | D17: 12 | E17: =INT(C17/D17) | F17: =C17-(E17*D17) | H17: =C17*G17
... A39: 34 | B39: Tanga (C) | D39: 10 | E39: =INT(C39/D39) | F39: =C39-(E39*D39) | H39: =C39*G39
A40: TOTALS | E40: =SUM(E6:E39) | H40: =SUM(H6:H39)
A43: DAILY EXPENSES
A45: Category | B45: Amount (Rs)
A46: Labor | B46: 0
A47: Transport | B47: 0
A48: Utilities | B48: 0
A49: Packaging | B49: 0
A50: Other | B50: 0
A51: Total Expenses | B51: =SUM(B46:B50)

Sheet Day 07
A1: DAILY SALES & EXPENSES - DAY 7
A3: DAILY SALES ENTRY (Packs)
A5: SKU # | B5: SKU Name | C5: Packs Sold | D5: Units/Ctn | E5: Ctns | F5: Packs | G5: Rs/Pack | H5: Total Rs
A6: 1 | B6: Kite Rs 10 | D6: 144 | E6: =INT(C6/D6) | F6: =C6-(E6*D6) | H6: =C6*G6
A7: 2 | B7: Kite Rs 20 | D7: 96 | E7: =INT(C7/D7) | F7: =C7-(E7*D7) | H7: =C7*G7
A8: 3 | B8: Kite Rs 50 | D8: 48 | E8: =INT(C8/D8) | F8: =C8-(E8*D8) | H8: =C8*G8
A9: 4 | B9: Kite Rs 99 | D9: 24 | E9: =INT(C9/D9) | F9: =C9-(E9*D9) | H9: =C9*G9
A10: 5 | B10: Kite 0.5kg | D10: 24 | E10: =INT(C10/D10) | F10: =C10-(E10*D10) | H10: =C10*G10
A11: 6 | B11: Kite 1kg | D11: 12 | E11: =INT(C11/D11) | F11: =C11-(E11*D11) | H11: =C11*G11
A12: 7 | B12: Kite 2kg | D12: 6 | E12: =INT(C12/D12) | F12: =C12-(E12*D12) | H12: =C12*G12
A13: 8 | B13: Burq Rs 10 | D13: 204 | E13: =INT(C13/D13) | F13: =C13-(E13*D13) | H13: =C13*G13
A14: 9 | B14: Burq Rs 20 | D14: 96 | E14: =INT(C14/D14) | F14: =C14-(E14*D14) | H14: =C14*G14
A15: 10 | B15: Burq Rs 50 | D15: 48 | E15: =INT(C15/D15) | F15: =C15-(E15*D15) | H15: =C15*G15
A16: 11 | B16: Burq Rs 99 | D16: 24 | E16: =INT(C16/D16) | F16: =C16-(E16*D16) | H16: =C16*G16
A17: 12 | B17: Burq 1kg | D17: 12 | E17: =INT(C17/D17) | F17: =C17-(E17*D17) | H17: =C17*G17
... A39: 34 | B39: Tanga (C) | D39: 10 | E39: =INT(C39/D39) | F39: =C39-(E39*D39) | H39: =C39*G39
A40: TOTALS | E40: =SUM(E6:E39) | H40: =SUM(H6:H39)
A43: DAILY EXPENSES
A45: Category | B45: Amount (Rs)
A46: Labor | B46: 0
A47: Transport | B47: 0
A48: Utilities | B48: 0
A49: Packaging | B49: 0
A50: Other | B50: 0
A51: Total Expenses | B51: =SUM(B46:B50)

Sheet Day 08
A1: DAILY SALES & EXPENSES - DAY 8
A3: DAILY SALES ENTRY (Packs)
A5: SKU # | B5: SKU Name | C5: Packs Sold | D5: Units/Ctn | E5: Ctns | F5: Packs | G5: Rs/Pack | H5: Total Rs
A6: 1 | B6: Kite Rs 10 | D6: 144 | E6: =INT(C6/D6) | F6: =C6-(E6*D6) | H6: =C6*G6
A7: 2 | B7: Kite Rs 20 | D7: 96 | E7: =INT(C7/D7) | F7: =C7-(E7*D7) | H7: =C7*G7
A8: 3 | B8: Kite Rs 50 | D8: 48 | E8: =INT(C8/D8) | F8: =C8-(E8*D8) | H8: =C8*G8
A9: 4 | B9: Kite Rs 99 | D9: 24 | E9: =INT(C9/D9) | F9: =C9-(E9*D9) | H9: =C9*G9
A10: 5 | B10: Kite 0.5kg | D10: 24 | E10: =INT(C10/D10) | F10: =C10-(E10*D10) | H10: =C10*G10
A11: 6 | B11: Kite 1kg | D11: 12 | E11: =INT(C11/D11) | F11: =C11-(E11*D11) | H11: =C11*G11
A12: 7 | B12: Kite 2kg | D12: 6 | E12: =INT(C12/D12) | F12: =C12-(E12*D12) | H12: =C12*G12
A13: 8 | B13: Burq Rs 10 | D13: 204 | E13: =INT(C13/D13) | F13: =C13-(E13*D13) | H13: =C13*G13
A14: 9 | B14: Burq Rs 20 | D14: 96 | E14: =INT(C14/D14) | F14: =C14-(E14*D14) | H14: =C14*G14
A15: 10 | B15: Burq Rs 50 | D15: 48 | E15: =INT(C15/D15) | F15: =C15-(E15*D15) | H15: =C15*G15
A16: 11 | B16: Burq Rs 99 | D16: 24 | E16: =INT(C16/D16) | F16: =C16-(E16*D16) | H16: =C16*G16
A17: 12 | B17: Burq 1kg | D17: 12 | E17: =INT(C17/D17) | F17: =C17-(E17*D17) | H17: =C17*G17
... A39: 34 | B39: Tanga (C) | D39: 10 | E39: =INT(C39/D39) | F39: =C39-(E39*D39) | H39: =C39*G39
A40: TOTALS | E40: =SUM(E6:E39) | H40: =SUM(H6:H39)
A43: DAILY EXPENSES
A45: Category | B45: Amount (Rs)
A46: Labor | B46: 0
A47: Transport | B47: 0
A48: Utilities | B48: 0
A49: Packaging | B49: 0
A50: Other | B50: 0
A51: Total Expenses | B51: =SUM(B46:B50)

Sheet Day 09
A1: DAILY SALES & EXPENSES - DAY 9
A3: DAILY SALES ENTRY (Packs)
A5: SKU # | B5: SKU Name | C5: Packs Sold | D5: Units/Ctn | E5: Ctns | F5: Packs | G5: Rs/Pack | H5: Total Rs
A6: 1 | B6: Kite Rs 10 | D6: 144 | E6: =INT(C6/D6) | F6: =C6-(E6*D6) | H6: =C6*G6
A7: 2 | B7: Kite Rs 20 | D7: 96 | E7: =INT(C7/D7) | F7: =C7-(E7*D7) | H7: =C7*G7
A8: 3 | B8: Kite Rs 50 | D8: 48 | E8: =INT(C8/D8) | F8: =C8-(E8*D8) | H8: =C8*G8
A9: 4 | B9: Kite Rs 99 | D9: 24 | E9: =INT(C9/D9) | F9: =C9-(E9*D9) | H9: =C9*G9
A10: 5 | B10: Kite 0.5kg | D10: 24 | E10: =INT(C10/D10) | F10: =C10-(E10*D10) | H10: =C10*G10
A11: 6 | B11: Kite 1kg | D11: 12 | E11: =INT(C11/D11) | F11: =C11-(E11*D11) | H11: =C11*G11
A12: 7 | B12: Kite 2kg | D12: 6 | E12: =INT(C12/D12) | F12: =C12-(E12*D12) | H12: =C12*G12
A13: 8 | B13: Burq Rs 10 | D13: 204 | E13: =INT(C13/D13) | F13: =C13-(E13*D13) | H13: =C13*G13
A14: 9 | B14: Burq Rs 20 | D14: 96 | E14: =INT(C14/D14) | F14: =C14-(E14*D14) | H14: =C14*G14
A15: 10 | B15: Burq Rs 50 | D15: 48 | E15: =INT(C15/D15) | F15: =C15-(E15*D15) | H15: =C15*G15
A16: 11 | B16: Burq Rs 99 | D16: 24 | E16: =INT(C16/D16) | F16: =C16-(E16*D16) | H16: =C16*G16
A17: 12 | B17: Burq 1kg | D17: 12 | E17: =INT(C17/D17) | F17: =C17-(E17*D17) | H17: =C17*G17
... A39: 34 | B39: Tanga (C) | D39: 10 | E39: =INT(C39/D39) | F39: =C39-(E39*D39) | H39: =C39*G39
A40: TOTALS | E40: =SUM(E6:E39) | H40: =SUM(H6:H39)
A43: DAILY EXPENSES
A45: Category | B45: Amount (Rs)
A46: Labor | B46: 0
A47: Transport | B47: 0
A48: Utilities | B48: 0
A49: Packaging | B49: 0
A50: Other | B50: 0
A51: Total Expenses | B51: =SUM(B46:B50)

Sheet Day 10
A1: DAILY SALES & EXPENSES - DAY 10
A3: DAILY SALES ENTRY (Packs)
A5: SKU # | B5: SKU Name | C5: Packs Sold | D5: Units/Ctn | E5: Ctns | F5: Packs | G5: Rs/Pack | H5: Total Rs
A6: 1 | B6: Kite Rs 10 | D6: 144 | E6: =INT(C6/D6) | F6: =C6-(E6*D6) | H6: =C6*G6
A7: 2 | B7: Kite Rs 20 | D7: 96 | E7: =INT(C7/D7) | F7: =C7-(E7*D7) | H7: =C7*G7
A8: 3 | B8: Kite Rs 50 | D8: 48 | E8: =INT(C8/D8) | F8: =C8-(E8*D8) | H8: =C8*G8
A9: 4 | B9: Kite Rs 99 | D9: 24 | E9: =INT(C9/D9) | F9: =C9-(E9*D9) | H9: =C9*G9
A10: 5 | B10: Kite 0.5kg | D10: 24 | E10: =INT(C10/D10) | F10: =C10-(E10*D10) | H10: =C10*G10
A11: 6 | B11: Kite 1kg | D11: 12 | E11: =INT(C11/D11) | F11: =C11-(E11*D11) | H11: =C11*G11
A12: 7 | B12: Kite 2kg | D12: 6 | E12: =INT(C12/D12) | F12: =C12-(E12*D12) | H12: =C12*G12
A13: 8 | B13: Burq Rs 10 | D13: 204 | E13: =INT(C13/D13) | F13: =C13-(E13*D13) | H13: =C13*G13
A14: 9 | B14: Burq Rs 20 | D14: 96 | E14: =INT(C14/D14) | F14: =C14-(E14*D14) | H14: =C14*G14
A15: 10 | B15: Burq Rs 50 | D15: 48 | E15: =INT(C15/D15) | F15: =C15-(E15*D15) | H15: =C15*G15
A16: 11 | B16: Burq Rs 99 | D16: 24 | E16: =INT(C16/D16) | F16: =C16-(E16*D16) | H16: =C16*G16
A17: 12 | B17: Burq 1kg | D17: 12 | E17: =INT(C17/D17) | F17: =C17-(E17*D17) | H17: =C17*G17
... A39: 34 | B39: Tanga (C) | D39: 10 | E39: =INT(C39/D39) | F39: =C39-(E39*D39) | H39: =C39*G39
A40: TOTALS | E40: =SUM(E6:E39) | H40: =SUM(H6:H39)
A43: DAILY EXPENSES
A45: Category | B45: Amount (Rs)
A46: Labor | B46: 0
A47: Transport | B47: 0
A48: Utilities | B48: 0
A49: Packaging | B49: 0
A50: Other | B50: 0
A51: Total Expenses | B51: =SUM(B46:B50)

Sheet Day 11
A1: DAILY SALES & EXPENSES - DAY 11
A3: DAILY SALES ENTRY (Packs)
A5: SKU # | B5: SKU Name | C5: Packs Sold | D5: Units/Ctn | E5: Ctns | F5: Packs | G5: Rs/Pack | H5: Total Rs
A6: 1 | B6: Kite Rs 10 | D6: 144 | E6: =INT(C6/D6) | F6: =C6-(E6*D6) | H6: =C6*G6
A7: 2 | B7: Kite Rs 20 | D7: 96 | E7: =INT(C7/D7) | F7: =C7-(E7*D7) | H7: =C7*G7
A8: 3 | B8: Kite Rs 50 | D8: 48 | E8: =INT(C8/D8) | F8: =C8-(E8*D8) | H8: =C8*G8
A9: 4 | B9: Kite Rs 99 | D9: 24 | E9: =INT(C9/D9) | F9: =C9-(E9*D9) | H9: =C9*G9
A10: 5 | B10: Kite 0.5kg | D10: 24 | E10: =INT(C10/D10) | F10: =C10-(E10*D10) | H10: =C10*G10
A11: 6 | B11: Kite 1kg | D11: 12 | E11: =INT(C11/D11) | F11: =C11-(E11*D11) | H11: =C11*G11
A12: 7 | B12: Kite 2kg | D12: 6 | E12: =INT(C12/D12) | F12: =C12-(E12*D12) | H12: =C12*G12
A13: 8 | B13: Burq Rs 10 | D13: 204 | E13: =INT(C13/D13) | F13: =C13-(E13*D13) | H13: =C13*G13
A14: 9 | B14: Burq Rs 20 | D14: 96 | E14: =INT(C14/D14) | F14: =C14-(E14*D14) | H14: =C14*G14
A15: 10 | B15: Burq Rs 50 | D15: 48 | E15: =INT(C15/D15) | F15: =C15-(E15*D15) | H15: =C15*G15
A16: 11 | B16: Burq Rs 99 | D16: 24 | E16: =INT(C16/D16) | F16: =C16-(E16*D16) | H16: =C16*G16
A17: 12 | B17: Burq 1kg | D17: 12 | E17: =INT(C17/D17) | F17: =C17-(E17*D17) | H17: =C17*G17
... A39: 34 | B39: Tanga (C) | D39: 10 | E39: =INT(C39/D39) | F39: =C39-(E39*D39) | H39: =C39*G39
A40: TOTALS | E40: =SUM(E6:E39) | H40: =SUM(H6:H39)
A43: DAILY EXPENSES
A45: Category | B45: Amount (Rs)
A46: Labor | B46: 0
A47: Transport | B47: 0
A48: Utilities | B48: 0
A49: Packaging | B49: 0
A50: Other | B50: 0
A51: Total Expenses | B51: =SUM(B46:B50)

Sheet Day 12
A1: DAILY SALES & EXPENSES - DAY 12
A3: DAILY SALES ENTRY (Packs)
A5: SKU # | B5: SKU Name | C5: Packs Sold | D5: Units/Ctn | E5: Ctns | F5: Packs | G5: Rs/Pack | H5: Total Rs
A6: 1 | B6: Kite Rs 10 | D6: 144 | E6: =INT(C6/D6) | F6: =C6-(E6*D6) | H6: =C6*G6
A7: 2 | B7: Kite Rs 20 | D7: 96 | E7: =INT(C7/D7) | F7: =C7-(E7*D7) | H7: =C7*G7
A8: 3 | B8: Kite Rs 50 | D8: 48 | E8: =INT(C8/D8) | F8: =C8-(E8*D8) | H8: =C8*G8
A9: 4 | B9: Kite Rs 99 | D9: 24 | E9: =INT(C9/D9) | F9: =C9-(E9*D9) | H9: =C9*G9
A10: 5 | B10: Kite 0.5kg | D10: 24 | E10: =INT(C10/D10) | F10: =C10-(E10*D10) | H10: =C10*G10
A11: 6 | B11: Kite 1kg | D11: 12 | E11: =INT(C11/D11) | F11: =C11-(E11*D11) | H11: =C11*G11
A12: 7 | B12: Kite 2kg | D12: 6 | E12: =INT(C12/D12) | F12: =C12-(E12*D12) | H12: =C12*G12
A13: 8 | B13: Burq Rs 10 | D13: 204 | E13: =INT(C13/D13) | F13: =C13-(E13*D13) | H13: =C13*G13
A14: 9 | B14: Burq Rs 20 | D14: 96 | E14: =INT(C14/D14) | F14: =C14-(E14*D14) | H14: =C14*G14
A15: 10 | B15: Burq Rs 50 | D15: 48 | E15: =INT(C15/D15) | F15: =C15-(E15*D15) | H15: =C15*G15
A16: 11 | B16: Burq Rs 99 | D16: 24 | E16: =INT(C16/D16) | F16: =C16-(E16*D16) | H16: =C16*G16
A17: 12 | B17: Burq 1kg | D17: 12 | E17: =INT(C17/D17) | F17: =C17-(E17*D17) | H17: =C17*G17
... A39: 34 | B39: Tanga (C) | D39: 10 | E39: =INT(C39/D39) | F39: =C39-(E39*D39) | H39: =C39*G39
A40: TOTALS | E40: =SUM(E6:E39) | H40: =SUM(H6:H39)
A43: DAILY EXPENSES
A45: Category | B45: Amount (Rs)
A46: Labor | B46: 0
A47: Transport | B47: 0
A48: Utilities | B48: 0
A49: Packaging | B49: 0
A50: Other | B50: 0
A51: Total Expenses | B51: =SUM(B46:B50)

Sheet Day 13
A1: DAILY SALES & EXPENSES - DAY 13
A3: DAILY SALES ENTRY (Packs)
A5: SKU # | B5: SKU Name | C5: Packs Sold | D5: Units/Ctn | E5: Ctns | F5: Packs | G5: Rs/Pack | H5: Total Rs
A6: 1 | B6: Kite Rs 10 | D6: 144 | E6: =INT(C6/D6) | F6: =C6-(E6*D6) | H6: =C6*G6
A7: 2 | B7: Kite Rs 20 | D7: 96 | E7: =INT(C7/D7) | F7: =C7-(E7*D7) | H7: =C7*G7
A8: 3 | B8: Kite Rs 50 | D8: 48 | E8: =INT(C8/D8) | F8: =C8-(E8*D8) | H8: =C8*G8
A9: 4 | B9: Kite Rs 99 | D9: 24 | E9: =INT(C9/D9) | F9: =C9-(E9*D9) | H9: =C9*G9
A10: 5 | B10: Kite 0.5kg | D10: 24 | E10: =INT(C10/D10) | F10: =C10-(E10*D10) | H10: =C10*G10
A11: 6 | B11: Kite 1kg | D11: 12 | E11: =INT(C11/D11) | F11: =C11-(E11*D11) | H11: =C11*G11
A12: 7 | B12: Kite 2kg | D12: 6 | E12: =INT(C12/D12) | F12: =C12-(E12*D12) | H12: =C12*G12
A13: 8 | B13: Burq Rs 10 | D13: 204 | E13: =INT(C13/D13) | F13: =C13-(E13*D13) | H13: =C13*G13
A14: 9 | B14: Burq Rs 20 | D14: 96 | E14: =INT(C14/D14) | F14: =C14-(E14*D14) | H14: =C14*G14
A15: 10 | B15: Burq Rs 50 | D15: 48 | E15: =INT(C15/D15) | F15: =C15-(E15*D15) | H15: =C15*G15
A16: 11 | B16: Burq Rs 99 | D16: 24 | E16: =INT(C16/D16) | F16: =C16-(E16*D16) | H16: =C16*G16
A17: 12 | B17: Burq 1kg | D17: 12 | E17: =INT(C17/D17) | F17: =C17-(E17*D17) | H17: =C17*G17
... A39: 34 | B39: Tanga (C) | D39: 10 | E39: =INT(C39/D39) | F39: =C39-(E39*D39) | H39: =C39*G39
A40: TOTALS | E40: =SUM(E6:E39) | H40: =SUM(H6:H39)
A43: DAILY EXPENSES
A45: Category | B45: Amount (Rs)
A46: Labor | B46: 0
A47: Transport | B47: 0
A48: Utilities | B48: 0
A49: Packaging | B49: 0
A50: Other | B50: 0
A51: Total Expenses | B51: =SUM(B46:B50)

Sheet Day 14
A1: DAILY SALES & EXPENSES - DAY 14
A3: DAILY SALES ENTRY (Packs)
A5: SKU # | B5: SKU Name | C5: Packs Sold | D5: Units/Ctn | E5: Ctns | F5: Packs | G5: Rs/Pack | H5: Total Rs
A6: 1 | B6: Kite Rs 10 | D6: 144 | E6: =INT(C6/D6) | F6: =C6-(E6*D6) | H6: =C6*G6
A7: 2 | B7: Kite Rs 20 | D7: 96 | E7: =INT(C7/D7) | F7: =C7-(E7*D7) | H7: =C7*G7
A8: 3 | B8: Kite Rs 50 | D8: 48 | E8: =INT(C8/D8) | F8: =C8-(E8*D8) | H8: =C8*G8
A9: 4 | B9: Kite Rs 99 | D9: 24 | E9: =INT(C9/D9) | F9: =C9-(E9*D9) | H9: =C9*G9
A10: 5 | B10: Kite 0.5kg | D10: 24 | E10: =INT(C10/D10) | F10: =C10-(E10*D10) | H10: =C10*G10
A11: 6 | B11: Kite 1kg | D11: 12 | E11: =INT(C11/D11) | F11: =C11-(E11*D11) | H11: =C11*G11
A12: 7 | B12: Kite 2kg | D12: 6 | E12: =INT(C12/D12) | F12: =C12-(E12*D12) | H12: =C12*G12
A13: 8 | B13: Burq Rs 10 | D13: 204 | E13: =INT(C13/D13) | F13: =C13-(E13*D13) | H13: =C13*G13
A14: 9 | B14: Burq Rs 20 | D14: 96 | E14: =INT(C14/D14) | F14: =C14-(E14*D14) | H14: =C14*G14
A15: 10 | B15: Burq Rs 50 | D15: 48 | E15: =INT(C15/D15) | F15: =C15-(E15*D15) | H15: =C15*G15
A16: 11 | B16: Burq Rs 99 | D16: 24 | E16: =INT(C16/D16) | F16: =C16-(E16*D16) | H16: =C16*G16
A17: 12 | B17: Burq 1kg | D17: 12 | E17: =INT(C17/D17) | F17: =C17-(E17*D17) | H17: =C17*G17
... A39: 34 | B39: Tanga (C) | D39: 10 | E39: =INT(C39/D39) | F39: =C39-(E39*D39) | H39: =C39*G39
A40: TOTALS | E40: =SUM(E6:E39) | H40: =SUM(H6:H39)
A43: DAILY EXPENSES
A45: Category | B45: Amount (Rs)
A46: Labor | B46: 0
A47: Transport | B47: 0
A48: Utilities | B48: 0
A49: Packaging | B49: 0
A50: Other | B50: 0
A51: Total Expenses | B51: =SUM(B46:B50)

Sheet Day 15
A1: DAILY SALES & EXPENSES - DAY 15
A3: DAILY SALES ENTRY (Packs)
A5: SKU # | B5: SKU Name | C5: Packs Sold | D5: Units/Ctn | E5: Ctns | F5: Packs | G5: Rs/Pack | H5: Total Rs
A6: 1 | B6: Kite Rs 10 | D6: 144 | E6: =INT(C6/D6) | F6: =C6-(E6*D6) | H6: =C6*G6
A7: 2 | B7: Kite Rs 20 | D7: 96 | E7: =INT(C7/D7) | F7: =C7-(E7*D7) | H7: =C7*G7
A8: 3 | B8: Kite Rs 50 | D8: 48 | E8: =INT(C8/D8) | F8: =C8-(E8*D8) | H8: =C8*G8
A9: 4 | B9: Kite Rs 99 | D9: 24 | E9: =INT(C9/D9) | F9: =C9-(E9*D9) | H9: =C9*G9
A10: 5 | B10: Kite 0.5kg | D10: 24 | E10: =INT(C10/D10) | F10: =C10-(E10*D10) | H10: =C10*G10
A11: 6 | B11: Kite 1kg | D11: 12 | E11: =INT(C11/D11) | F11: =C11-(E11*D11) | H11: =C11*G11
A12: 7 | B12: Kite 2kg | D12: 6 | E12: =INT(C12/D12) | F12: =C12-(E12*D12) | H12: =C12*G12
A13: 8 | B13: Burq Rs 10 | D13: 204 | E13: =INT(C13/D13) | F13: =C13-(E13*D13) | H13: =C13*G13
A14: 9 | B14: Burq Rs 20 | D14: 96 | E14: =INT(C14/D14) | F14: =C14-(E14*D14) | H14: =C14*G14
A15: 10 | B15: Burq Rs 50 | D15: 48 | E15: =INT(C15/D15) | F15: =C15-(E15*D15) | H15: =C15*G15
A16: 11 | B16: Burq Rs 99 | D16: 24 | E16: =INT(C16/D16) | F16: =C16-(E16*D16) | H16: =C16*G16
A17: 12 | B17: Burq 1kg | D17: 12 | E17: =INT(C17/D17) | F17: =C17-(E17*D17) | H17: =C17*G17
... A39: 34 | B39: Tanga (C) | D39: 10 | E39: =INT(C39/D39) | F39: =C39-(E39*D39) | H39: =C39*G39
A40: TOTALS | E40: =SUM(E6:E39) | H40: =SUM(H6:H39)
A43: DAILY EXPENSES
A45: Category | B45: Amount (Rs)
A46: Labor | B46: 0
A47: Transport | B47: 0
A48: Utilities | B48: 0
A49: Packaging | B49: 0
A50: Other | B50: 0
A51: Total Expenses | B51: =SUM(B46:B50)

Sheet Day 16
A1: DAILY SALES & EXPENSES - DAY 16
A3: DAILY SALES ENTRY (Packs)
A5: SKU # | B5: SKU Name | C5: Packs Sold | D5: Units/Ctn | E5: Ctns | F5: Packs | G5: Rs/Pack | H5: Total Rs
A6: 1 | B6: Kite Rs 10 | D6: 144 | E6: =INT(C6/D6) | F6: =C6-(E6*D6) | H6: =C6*G6
A7: 2 | B7: Kite Rs 20 | D7: 96 | E7: =INT(C7/D7) | F7: =C7-(E7*D7) | H7: =C7*G7
A8: 3 | B8: Kite Rs 50 | D8: 48 | E8: =INT(C8/D8) | F8: =C8-(E8*D8) | H8: =C8*G8
A9: 4 | B9: Kite Rs 99 | D9: 24 | E9: =INT(C9/D9) | F9: =C9-(E9*D9) | H9: =C9*G9
A10: 5 | B10: Kite 0.5kg | D10: 24 | E10: =INT(C10/D10) | F10: =C10-(E10*D10) | H10: =C10*G10
A11: 6 | B11: Kite 1kg | D11: 12 | E11: =INT(C11/D11) | F11: =C11-(E11*D11) | H11: =C11*G11
A12: 7 | B12: Kite 2kg | D12: 6 | E12: =INT(C12/D12) | F12: =C12-(E12*D12) | H12: =C12*G12
A13: 8 | B13: Burq Rs 10 | D13: 204 | E13: =INT(C13/D13) | F13: =C13-(E13*D13) | H13: =C13*G13
A14: 9 | B14: Burq Rs 20 | D14: 96 | E14: =INT(C14/D14) | F14: =C14-(E14*D14) | H14: =C14*G14
A15: 10 | B15: Burq Rs 50 | D15: 48 | E15: =INT(C15/D15) | F15: =C15-(E15*D15) | H15: =C15*G15
A16: 11 | B16: Burq Rs 99 | D16: 24 | E16: =INT(C16/D16) | F16: =C16-(E16*D16) | H16: =C16*G16
A17: 12 | B17: Burq 1kg | D17: 12 | E17: =INT(C17/D17) | F17: =C17-(E17*D17) | H17: =C17*G17
... A39: 34 | B39: Tanga (C) | D39: 10 | E39: =INT(C39/D39) | F39: =C39-(E39*D39) | H39: =C39*G39
A40: TOTALS | E40: =SUM(E6:E39) | H40: =SUM(H6:H39)
A43: DAILY EXPENSES
A45: Category | B45: Amount (Rs)
A46: Labor | B46: 0
A47: Transport | B47: 0
A48: Utilities | B48: 0
A49: Packaging | B49: 0
A50: Other | B50: 0
A51: Total Expenses | B51: =SUM(B46:B50)

Sheet Day 17
A1: DAILY SALES & EXPENSES - DAY 17
A3: DAILY SALES ENTRY (Packs)
A5: SKU # | B5: SKU Name | C5: Packs Sold | D5: Units/Ctn | E5: Ctns | F5: Packs | G5: Rs/Pack | H5: Total Rs
A6: 1 | B6: Kite Rs 10 | D6: 144 | E6: =INT(C6/D6) | F6: =C6-(E6*D6) | H6: =C6*G6
A7: 2 | B7: Kite Rs 20 | D7: 96 | E7: =INT(C7/D7) | F7: =C7-(E7*D7) | H7: =C7*G7
A8: 3 | B8: Kite Rs 50 | D8: 48 | E8: =INT(C8/D8) | F8: =C8-(E8*D8) | H8: =C8*G8
A9: 4 | B9: Kite Rs 99 | D9: 24 | E9: =INT(C9/D9) | F9: =C9-(E9*D9) | H9: =C9*G9
A10: 5 | B10: Kite 0.5kg | D10: 24 | E10: =INT(C10/D10) | F10: =C10-(E10*D10) | H10: =C10*G10
A11: 6 | B11: Kite 1kg | D11: 12 | E11: =INT(C11/D11) | F11: =C11-(E11*D11) | H11: =C11*G11
A12: 7 | B12: Kite 2kg | D12: 6 | E12: =INT(C12/D12) | F12: =C12-(E12*D12) | H12: =C12*G12
A13: 8 | B13: Burq Rs 10 | D13: 204 | E13: =INT(C13/D13) | F13: =C13-(E13*D13) | H13: =C13*G13
A14: 9 | B14: Burq Rs 20 | D14: 96 | E14: =INT(C14/D14) | F14: =C14-(E14*D14) | H14: =C14*G14
A15: 10 | B15: Burq Rs 50 | D15: 48 | E15: =INT(C15/D15) | F15: =C15-(E15*D15) | H15: =C15*G15
A16: 11 | B16: Burq Rs 99 | D16: 24 | E16: =INT(C16/D16) | F16: =C16-(E16*D16) | H16: =C16*G16
A17: 12 | B17: Burq 1kg | D17: 12 | E17: =INT(C17/D17) | F17: =C17-(E17*D17) | H17: =C17*G17
... A39: 34 | B39: Tanga (C) | D39: 10 | E39: =INT(C39/D39) | F39: =C39-(E39*D39) | H39: =C39*G39
A40: TOTALS | E40: =SUM(E6:E39) | H40: =SUM(H6:H39)
A43: DAILY EXPENSES
A45: Category | B45: Amount (Rs)
A46: Labor | B46: 0
A47: Transport | B47: 0
A48: Utilities | B48: 0
A49: Packaging | B49: 0
A50: Other | B50: 0
A51: Total Expenses | B51: =SUM(B46:B50)

Sheet Day 18
A1: DAILY SALES & EXPENSES - DAY 18
A3: DAILY SALES ENTRY (Packs)
A5: SKU # | B5: SKU Name | C5: Packs Sold | D5: Units/Ctn | E5: Ctns | F5: Packs | G5: Rs/Pack | H5: Total Rs
A6: 1 | B6: Kite Rs 10 | D6: 144 | E6: =INT(C6/D6) | F6: =C6-(E6*D6) | H6: =C6*G6
A7: 2 | B7: Kite Rs 20 | D7: 96 | E7: =INT(C7/D7) | F7: =C7-(E7*D7) | H7: =C7*G7
A8: 3 | B8: Kite Rs 50 | D8: 48 | E8: =INT(C8/D8) | F8: =C8-(E8*D8) | H8: =C8*G8
A9: 4 | B9: Kite Rs 99 | D9: 24 | E9: =INT(C9/D9) | F9: =C9-(E9*D9) | H9: =C9*G9
A10: 5 | B10: Kite 0.5kg | D10: 24 | E10: =INT(C10/D10) | F10: =C10-(E10*D10) | H10: =C10*G10
A11: 6 | B11: Kite 1kg | D11: 12 | E11: =INT(C11/D11) | F11: =C11-(E11*D11) | H11: =C11*G11
A12: 7 | B12: Kite 2kg | D12: 6 | E12: =INT(C12/D12) | F12: =C12-(E12*D12) | H12: =C12*G12
A13: 8 | B13: Burq Rs 10 | D13: 204 | E13: =INT(C13/D13) | F13: =C13-(E13*D13) | H13: =C13*G13
A14: 9 | B14: Burq Rs 20 | D14: 96 | E14: =INT(C14/D14) | F14: =C14-(E14*D14) | H14: =C14*G14
A15: 10 | B15: Burq Rs 50 | D15: 48 | E15: =INT(C15/D15) | F15: =C15-(E15*D15) | H15: =C15*G15
A16: 11 | B16: Burq Rs 99 | D16: 24 | E16: =INT(C16/D16) | F16: =C16-(E16*D16) | H16: =C16*G16
A17: 12 | B17: Burq 1kg | D17: 12 | E17: =INT(C17/D17) | F17: =C17-(E17*D17) | H17: =C17*G17
... A39: 34 | B39: Tanga (C) | D39: 10 | E39: =INT(C39/D39) | F39: =C39-(E39*D39) | H39: =C39*G39
A40: TOTALS | E40: =SUM(E6:E39) | H40: =SUM(H6:H39)
A43: DAILY EXPENSES
A45: Category | B45: Amount (Rs)
A46: Labor | B46: 0
A47: Transport | B47: 0
A48: Utilities | B48: 0
A49: Packaging | B49: 0
A50: Other | B50: 0
A51: Total Expenses | B51: =SUM(B46:B50)

Sheet Day 19
A1: DAILY SALES & EXPENSES - DAY 19
A3: DAILY SALES ENTRY (Packs)
A5: SKU # | B5: SKU Name | C5: Packs Sold | D5: Units/Ctn | E5: Ctns | F5: Packs | G5: Rs/Pack | H5: Total Rs
A6: 1 | B6: Kite Rs 10 | D6: 144 | E6: =INT(C6/D6) | F6: =C6-(E6*D6) | H6: =C6*G6
A7: 2 | B7: Kite Rs 20 | D7: 96 | E7: =INT(C7/D7) | F7: =C7-(E7*D7) | H7: =C7*G7
A8: 3 | B8: Kite Rs 50 | D8: 48 | E8: =INT(C8/D8) | F8: =C8-(E8*D8) | H8: =C8*G8
A9: 4 | B9: Kite Rs 99 | D9: 24 | E9: =INT(C9/D9) | F9: =C9-(E9*D9) | H9: =C9*G9
A10: 5 | B10: Kite 0.5kg | D10: 24 | E10: =INT(C10/D10) | F10: =C10-(E10*D10) | H10: =C10*G10
A11: 6 | B11: Kite 1kg | D11: 12 | E11: =INT(C11/D11) | F11: =C11-(E11*D11) | H11: =C11*G11
A12: 7 | B12: Kite 2kg | D12: 6 | E12: =INT(C12/D12) | F12: =C12-(E12*D12) | H12: =C12*G12
A13: 8 | B13: Burq Rs 10 | D13: 204 | E13: =INT(C13/D13) | F13: =C13-(E13*D13) | H13: =C13*G13
A14: 9 | B14: Burq Rs 20 | D14: 96 | E14: =INT(C14/D14) | F14: =C14-(E14*D14) | H14: =C14*G14
A15: 10 | B15: Burq Rs 50 | D15: 48 | E15: =INT(C15/D15) | F15: =C15-(E15*D15) | H15: =C15*G15
A16: 11 | B16: Burq Rs 99 | D16: 24 | E16: =INT(C16/D16) | F16: =C16-(E16*D16) | H16: =C16*G16
A17: 12 | B17: Burq 1kg | D17: 12 | E17: =INT(C17/D17) | F17: =C17-(E17*D17) | H17: =C17*G17
... A39: 34 | B39: Tanga (C) | D39: 10 | E39: =INT(C39/D39) | F39: =C39-(E39*D39) | H39: =C39*G39
A40: TOTALS | E40: =SUM(E6:E39) | H40: =SUM(H6:H39)
A43: DAILY EXPENSES
A45: Category | B45: Amount (Rs)
A46: Labor | B46: 0
A47: Transport | B47: 0
A48: Utilities | B48: 0
A49: Packaging | B49: 0
A50: Other | B50: 0
A51: Total Expenses | B51: =SUM(B46:B50)

Sheet Day 20
A1: DAILY SALES & EXPENSES - DAY 20
A3: DAILY SALES ENTRY (Packs)
A5: SKU # | B5: SKU Name | C5: Packs Sold | D5: Units/Ctn | E5: Ctns | F5: Packs | G5: Rs/Pack | H5: Total Rs
A6: 1 | B6: Kite Rs 10 | D6: 144 | E6: =INT(C6/D6) | F6: =C6-(E6*D6) | H6: =C6*G6
A7: 2 | B7: Kite Rs 20 | D7: 96 | E7: =INT(C7/D7) | F7: =C7-(E7*D7) | H7: =C7*G7
A8: 3 | B8: Kite Rs 50 | D8: 48 | E8: =INT(C8/D8) | F8: =C8-(E8*D8) | H8: =C8*G8
A9: 4 | B9: Kite Rs 99 | D9: 24 | E9: =INT(C9/D9) | F9: =C9-(E9*D9) | H9: =C9*G9
A10: 5 | B10: Kite 0.5kg | D10: 24 | E10: =INT(C10/D10) | F10: =C10-(E10*D10) | H10: =C10*G10
A11: 6 | B11: Kite 1kg | D11: 12 | E11: =INT(C11/D11) | F11: =C11-(E11*D11) | H11: =C11*G11
A12: 7 | B12: Kite 2kg | D12: 6 | E12: =INT(C12/D12) | F12: =C12-(E12*D12) | H12: =C12*G12
A13: 8 | B13: Burq Rs 10 | D13: 204 | E13: =INT(C13/D13) | F13: =C13-(E13*D13) | H13: =C13*G13
A14: 9 | B14: Burq Rs 20 | D14: 96 | E14: =INT(C14/D14) | F14: =C14-(E14*D14) | H14: =C14*G14
A15: 10 | B15: Burq Rs 50 | D15: 48 | E15: =INT(C15/D15) | F15: =C15-(E15*D15) | H15: =C15*G15
A16: 11 | B16: Burq Rs 99 | D16: 24 | E16: =INT(C16/D16) | F16: =C16-(E16*D16) | H16: =C16*G16
A17: 12 | B17: Burq 1kg | D17: 12 | E17: =INT(C17/D17) | F17: =C17-(E17*D17) | H17: =C17*G17
... A39: 34 | B39: Tanga (C) | D39: 10 | E39: =INT(C39/D39) | F39: =C39-(E39*D39) | H39: =C39*G39
A40: TOTALS | E40: =SUM(E6:E39) | H40: =SUM(H6:H39)
A43: DAILY EXPENSES
A45: Category | B45: Amount (Rs)
A46: Labor | B46: 0
A47: Transport | B47: 0
A48: Utilities | B48: 0
A49: Packaging | B49: 0
A50: Other | B50: 0
A51: Total Expenses | B51: =SUM(B46:B50)

Sheet Day 21
A1: DAILY SALES & EXPENSES - DAY 21
A3: DAILY SALES ENTRY (Packs)
A5: SKU # | B5: SKU Name | C5: Packs Sold | D5: Units/Ctn | E5: Ctns | F5: Packs | G5: Rs/Pack | H5: Total Rs
A6: 1 | B6: Kite Rs 10 | D6: 144 | E6: =INT(C6/D6) | F6: =C6-(E6*D6) | H6: =C6*G6
A7: 2 | B7: Kite Rs 20 | D7: 96 | E7: =INT(C7/D7) | F7: =C7-(E7*D7) | H7: =C7*G7
A8: 3 | B8: Kite Rs 50 | D8: 48 | E8: =INT(C8/D8) | F8: =C8-(E8*D8) | H8: =C8*G8
A9: 4 | B9: Kite Rs 99 | D9: 24 | E9: =INT(C9/D9) | F9: =C9-(E9*D9) | H9: =C9*G9
A10: 5 | B10: Kite 0.5kg | D10: 24 | E10: =INT(C10/D10) | F10: =C10-(E10*D10) | H10: =C10*G10
A11: 6 | B11: Kite 1kg | D11: 12 | E11: =INT(C11/D11) | F11: =C11-(E11*D11) | H11: =C11*G11
A12: 7 | B12: Kite 2kg | D12: 6 | E12: =INT(C12/D12) | F12: =C12-(E12*D12) | H12: =C12*G12
A13: 8 | B13: Burq Rs 10 | D13: 204 | E13: =INT(C13/D13) | F13: =C13-(E13*D13) | H13: =C13*G13
A14: 9 | B14: Burq Rs 20 | D14: 96 | E14: =INT(C14/D14) | F14: =C14-(E14*D14) | H14: =C14*G14
A15: 10 | B15: Burq Rs 50 | D15: 48 | E15: =INT(C15/D15) | F15: =C15-(E15*D15) | H15: =C15*G15
A16: 11 | B16: Burq Rs 99 | D16: 24 | E16: =INT(C16/D16) | F16: =C16-(E16*D16) | H16: =C16*G16
A17: 12 | B17: Burq 1kg | D17: 12 | E17: =INT(C17/D17) | F17: =C17-(E17*D17) | H17: =C17*G17
... A39: 34 | B39: Tanga (C) | D39: 10 | E39: =INT(C39/D39) | F39: =C39-(E39*D39) | H39: =C39*G39
A40: TOTALS | E40: =SUM(E6:E39) | H40: =SUM(H6:H39)
A43: DAILY EXPENSES
A45: Category | B45: Amount (Rs)
A46: Labor | B46: 0
A47: Transport | B47: 0
A48: Utilities | B48: 0
A49: Packaging | B49: 0
A50: Other | B50: 0
A51: Total Expenses | B51: =SUM(B46:B50)

Sheet Day 22
A1: DAILY SALES & EXPENSES - DAY 22
A3: DAILY SALES ENTRY (Packs)
A5: SKU # | B5: SKU Name | C5: Packs Sold | D5: Units/Ctn | E5: Ctns | F5: Packs | G5: Rs/Pack | H5: Total Rs
A6: 1 | B6: Kite Rs 10 | D6: 144 | E6: =INT(C6/D6) | F6: =C6-(E6*D6) | H6: =C6*G6
A7: 2 | B7: Kite Rs 20 | D7: 96 | E7: =INT(C7/D7) | F7: =C7-(E7*D7) | H7: =C7*G7
A8: 3 | B8: Kite Rs 50 | D8: 48 | E8: =INT(C8/D8) | F8: =C8-(E8*D8) | H8: =C8*G8
A9: 4 | B9: Kite Rs 99 | D9: 24 | E9: =INT(C9/D9) | F9: =C9-(E9*D9) | H9: =C9*G9
A10: 5 | B10: Kite 0.5kg | D10: 24 | E10: =INT(C10/D10) | F10: =C10-(E10*D10) | H10: =C10*G10
A11: 6 | B11: Kite 1kg | D11: 12 | E11: =INT(C11/D11) | F11: =C11-(E11*D11) | H11: =C11*G11
A12: 7 | B12: Kite 2kg | D12: 6 | E12: =INT(C12/D12) | F12: =C12-(E12*D12) | H12: =C12*G12
A13: 8 | B13: Burq Rs 10 | D13: 204 | E13: =INT(C13/D13) | F13: =C13-(E13*D13) | H13: =C13*G13
A14: 9 | B14: Burq Rs 20 | D14: 96 | E14: =INT(C14/D14) | F14: =C14-(E14*D14) | H14: =C14*G14
A15: 10 | B15: Burq Rs 50 | D15: 48 | E15: =INT(C15/D15) | F15: =C15-(E15*D15) | H15: =C15*G15
A16: 11 | B16: Burq Rs 99 | D16: 24 | E16: =INT(C16/D16) | F16: =C16-(E16*D16) | H16: =C16*G16
A17: 12 | B17: Burq 1kg | D17: 12 | E17: =INT(C17/D17) | F17: =C17-(E17*D17) | H17: =C17*G17
... A39: 34 | B39: Tanga (C) | D39: 10 | E39: =INT(C39/D39) | F39: =C39-(E39*D39) | H39: =C39*G39
A40: TOTALS | E40: =SUM(E6:E39) | H40: =SUM(H6:H39)
A43: DAILY EXPENSES
A45: Category | B45: Amount (Rs)
A46: Labor | B46: 0
A47: Transport | B47: 0
A48: Utilities | B48: 0
A49: Packaging | B49: 0
A50: Other | B50: 0
A51: Total Expenses | B51: =SUM(B46:B50)

Sheet Day 23
A1: DAILY SALES & EXPENSES - DAY 23
A3: DAILY SALES ENTRY (Packs)
A5: SKU # | B5: SKU Name | C5: Packs Sold | D5: Units/Ctn | E5: Ctns | F5: Packs | G5: Rs/Pack | H5: Total Rs
A6: 1 | B6: Kite Rs 10 | D6: 144 | E6: =INT(C6/D6) | F6: =C6-(E6*D6) | H6: =C6*G6
A7: 2 | B7: Kite Rs 20 | D7: 96 | E7: =INT(C7/D7) | F7: =C7-(E7*D7) | H7: =C7*G7
A8: 3 | B8: Kite Rs 50 | D8: 48 | E8: =INT(C8/D8) | F8: =C8-(E8*D8) | H8: =C8*G8
A9: 4 | B9: Kite Rs 99 | D9: 24 | E9: =INT(C9/D9) | F9: =C9-(E9*D9) | H9: =C9*G9
A10: 5 | B10: Kite 0.5kg | D10: 24 | E10: =INT(C10/D10) | F10: =C10-(E10*D10) | H10: =C10*G10
A11: 6 | B11: Kite 1kg | D11: 12 | E11: =INT(C11/D11) | F11: =C11-(E11*D11) | H11: =C11*G11
A12: 7 | B12: Kite 2kg | D12: 6 | E12: =INT(C12/D12) | F12: =C12-(E12*D12) | H12: =C12*G12
A13: 8 | B13: Burq Rs 10 | D13: 204 | E13: =INT(C13/D13) | F13: =C13-(E13*D13) | H13: =C13*G13
A14: 9 | B14: Burq Rs 20 | D14: 96 | E14: =INT(C14/D14) | F14: =C14-(E14*D14) | H14: =C14*G14
A15: 10 | B15: Burq Rs 50 | D15: 48 | E15: =INT(C15/D15) | F15: =C15-(E15*D15) | H15: =C15*G15
A16: 11 | B16: Burq Rs 99 | D16: 24 | E16: =INT(C16/D16) | F16: =C16-(E16*D16) | H16: =C16*G16
A17: 12 | B17: Burq 1kg | D17: 12 | E17: =INT(C17/D17) | F17: =C17-(E17*D17) | H17: =C17*G17
... A39: 34 | B39: Tanga (C) | D39: 10 | E39: =INT(C39/D39) | F39: =C39-(E39*D39) | H39: =C39*G39
A40: TOTALS | E40: =SUM(E6:E39) | H40: =SUM(H6:H39)
A43: DAILY EXPENSES
A45: Category | B45: Amount (Rs)
A46: Labor | B46: 0
A47: Transport | B47: 0
A48: Utilities | B48: 0
A49: Packaging | B49: 0
A50: Other | B50: 0
A51: Total Expenses | B51: =SUM(B46:B50)

Sheet Day 24
A1: DAILY SALES & EXPENSES - DAY 24
A3: DAILY SALES ENTRY (Packs)
A5: SKU # | B5: SKU Name | C5: Packs Sold | D5: Units/Ctn | E5: Ctns | F5: Packs | G5: Rs/Pack | H5: Total Rs
A6: 1 | B6: Kite Rs 10 | D6: 144 | E6: =INT(C6/D6) | F6: =C6-(E6*D6) | H6: =C6*G6
A7: 2 | B7: Kite Rs 20 | D7: 96 | E7: =INT(C7/D7) | F7: =C7-(E7*D7) | H7: =C7*G7
A8: 3 | B8: Kite Rs 50 | D8: 48 | E8: =INT(C8/D8) | F8: =C8-(E8*D8) | H8: =C8*G8
A9: 4 | B9: Kite Rs 99 | D9: 24 | E9: =INT(C9/D9) | F9: =C9-(E9*D9) | H9: =C9*G9
A10: 5 | B10: Kite 0.5kg | D10: 24 | E10: =INT(C10/D10) | F10: =C10-(E10*D10) | H10: =C10*G10
A11: 6 | B11: Kite 1kg | D11: 12 | E11: =INT(C11/D11) | F11: =C11-(E11*D11) | H11: =C11*G11
A12: 7 | B12: Kite 2kg | D12: 6 | E12: =INT(C12/D12) | F12: =C12-(E12*D12) | H12: =C12*G12
A13: 8 | B13: Burq Rs 10 | D13: 204 | E13: =INT(C13/D13) | F13: =C13-(E13*D13) | H13: =C13*G13
A14: 9 | B14: Burq Rs 20 | D14: 96 | E14: =INT(C14/D14) | F14: =C14-(E14*D14) | H14: =C14*G14
A15: 10 | B15: Burq Rs 50 | D15: 48 | E15: =INT(C15/D15) | F15: =C15-(E15*D15) | H15: =C15*G15
A16: 11 | B16: Burq Rs 99 | D16: 24 | E16: =INT(C16/D16) | F16: =C16-(E16*D16) | H16: =C16*G16
A17: 12 | B17: Burq 1kg | D17: 12 | E17: =INT(C17/D17) | F17: =C17-(E17*D17) | H17: =C17*G17
... A39: 34 | B39: Tanga (C) | D39: 10 | E39: =INT(C39/D39) | F39: =C39-(E39*D39) | H39: =C39*G39
A40: TOTALS | E40: =SUM(E6:E39) | H40: =SUM(H6:H39)
A43: DAILY EXPENSES
A45: Category | B45: Amount (Rs)
A46: Labor | B46: 0
A47: Transport | B47: 0
A48: Utilities | B48: 0
A49: Packaging | B49: 0
A50: Other | B50: 0
A51: Total Expenses | B51: =SUM(B46:B50)

Sheet Day 25
A1: DAILY SALES & EXPENSES - DAY 25
A3: DAILY SALES ENTRY (Packs)
A5: SKU # | B5: SKU Name | C5: Packs Sold | D5: Units/Ctn | E5: Ctns | F5: Packs | G5: Rs/Pack | H5: Total Rs
A6: 1 | B6: Kite Rs 10 | D6: 144 | E6: =INT(C6/D6) | F6: =C6-(E6*D6) | H6: =C6*G6
A7: 2 | B7: Kite Rs 20 | D7: 96 | E7: =INT(C7/D7) | F7: =C7-(E7*D7) | H7: =C7*G7
A8: 3 | B8: Kite Rs 50 | D8: 48 | E8: =INT(C8/D8) | F8: =C8-(E8*D8) | H8: =C8*G8
A9: 4 | B9: Kite Rs 99 | D9: 24 | E9: =INT(C9/D9) | F9: =C9-(E9*D9) | H9: =C9*G9
A10: 5 | B10: Kite 0.5kg | D10: 24 | E10: =INT(C10/D10) | F10: =C10-(E10*D10) | H10: =C10*G10
A11: 6 | B11: Kite 1kg | D11: 12 | E11: =INT(C11/D11) | F11: =C11-(E11*D11) | H11: =C11*G11
A12: 7 | B12: Kite 2kg | D12: 6 | E12: =INT(C12/D12) | F12: =C12-(E12*D12) | H12: =C12*G12
A13: 8 | B13: Burq Rs 10 | D13: 204 | E13: =INT(C13/D13) | F13: =C13-(E13*D13) | H13: =C13*G13
A14: 9 | B14: Burq Rs 20 | D14: 96 | E14: =INT(C14/D14) | F14: =C14-(E14*D14) | H14: =C14*G14
A15: 10 | B15: Burq Rs 50 | D15: 48 | E15: =INT(C15/D15) | F15: =C15-(E15*D15) | H15: =C15*G15
A16: 11 | B16: Burq Rs 99 | D16: 24 | E16: =INT(C16/D16) | F16: =C16-(E16*D16) | H16: =C16*G16
A17: 12 | B17: Burq 1kg | D17: 12 | E17: =INT(C17/D17) | F17: =C17-(E17*D17) | H17: =C17*G17
... A39: 34 | B39: Tanga (C) | D39: 10 | E39: =INT(C39/D39) | F39: =C39-(E39*D39) | H39: =C39*G39
A40: TOTALS | E40: =SUM(E6:E39) | H40: =SUM(H6:H39)
A43: DAILY EXPENSES
A45: Category | B45: Amount (Rs)
A46: Labor | B46: 0
A47: Transport | B47: 0
A48: Utilities | B48: 0
A49: Packaging | B49: 0
A50: Other | B50: 0
A51: Total Expenses | B51: =SUM(B46:B50)

Sheet Day 26
A1: DAILY SALES & EXPENSES - DAY 26
A3: DAILY SALES ENTRY (Packs)
A5: SKU # | B5: SKU Name | C5: Packs Sold | D5: Units/Ctn | E5: Ctns | F5: Packs | G5: Rs/Pack | H5: Total Rs
A6: 1 | B6: Kite Rs 10 | D6: 144 | E6: =INT(C6/D6) | F6: =C6-(E6*D6) | H6: =C6*G6
A7: 2 | B7: Kite Rs 20 | D7: 96 | E7: =INT(C7/D7) | F7: =C7-(E7*D7) | H7: =C7*G7
A8: 3 | B8: Kite Rs 50 | D8: 48 | E8: =INT(C8/D8) | F8: =C8-(E8*D8) | H8: =C8*G8
A9: 4 | B9: Kite Rs 99 | D9: 24 | E9: =INT(C9/D9) | F9: =C9-(E9*D9) | H9: =C9*G9
A10: 5 | B10: Kite 0.5kg | D10: 24 | E10: =INT(C10/D10) | F10: =C10-(E10*D10) | H10: =C10*G10
A11: 6 | B11: Kite 1kg | D11: 12 | E11: =INT(C11/D11) | F11: =C11-(E11*D11) | H11: =C11*G11
A12: 7 | B12: Kite 2kg | D12: 6 | E12: =INT(C12/D12) | F12: =C12-(E12*D12) | H12: =C12*G12
A13: 8 | B13: Burq Rs 10 | D13: 204 | E13: =INT(C13/D13) | F13: =C13-(E13*D13) | H13: =C13*G13
A14: 9 | B14: Burq Rs 20 | D14: 96 | E14: =INT(C14/D14) | F14: =C14-(E14*D14) | H14: =C14*G14
A15: 10 | B15: Burq Rs 50 | D15: 48 | E15: =INT(C15/D15) | F15: =C15-(E15*D15) | H15: =C15*G15
A16: 11 | B16: Burq Rs 99 | D16: 24 | E16: =INT(C16/D16) | F16: =C16-(E16*D16) | H16: =C16*G16
A17: 12 | B17: Burq 1kg | D17: 12 | E17: =INT(C17/D17) | F17: =C17-(E17*D17) | H17: =C17*G17
... A39: 34 | B39: Tanga (C) | D39: 10 | E39: =INT(C39/D39) | F39: =C39-(E39*D39) | H39: =C39*G39
A40: TOTALS | E40: =SUM(E6:E39) | H40: =SUM(H6:H39)
A43: DAILY EXPENSES
A45: Category | B45: Amount (Rs)
A46: Labor | B46: 0
A47: Transport | B47: 0
A48: Utilities | B48: 0
A49: Packaging | B49: 0
A50: Other | B50: 0
A51: Total Expenses | B51: =SUM(B46:B50)

Sheet Day 27
A1: DAILY SALES & EXPENSES - DAY 27
A3: DAILY SALES ENTRY (Packs)
A5: SKU # | B5: SKU Name | C5: Packs Sold | D5: Units/Ctn | E5: Ctns | F5: Packs | G5: Rs/Pack | H5: Total Rs
A6: 1 | B6: Kite Rs 10 | D6: 144 | E6: =INT(C6/D6) | F6: =C6-(E6*D6) | H6: =C6*G6
A7: 2 | B7: Kite Rs 20 | D7: 96 | E7: =INT(C7/D7) | F7: =C7-(E7*D7) | H7: =C7*G7
A8: 3 | B8: Kite Rs 50 | D8: 48 | E8: =INT(C8/D8) | F8: =C8-(E8*D8) | H8: =C8*G8
A9: 4 | B9: Kite Rs 99 | D9: 24 | E9: =INT(C9/D9) | F9: =C9-(E9*D9) | H9: =C9*G9
A10: 5 | B10: Kite 0.5kg | D10: 24 | E10: =INT(C10/D10) | F10: =C10-(E10*D10) | H10: =C10*G10
A11: 6 | B11: Kite 1kg | D11: 12 | E11: =INT(C11/D11) | F11: =C11-(E11*D11) | H11: =C11*G11
A12: 7 | B12: Kite 2kg | D12: 6 | E12: =INT(C12/D12) | F12: =C12-(E12*D12) | H12: =C12*G12
A13: 8 | B13: Burq Rs 10 | D13: 204 | E13: =INT(C13/D13) | F13: =C13-(E13*D13) | H13: =C13*G13
A14: 9 | B14: Burq Rs 20 | D14: 96 | E14: =INT(C14/D14) | F14: =C14-(E14*D14) | H14: =C14*G14
A15: 10 | B15: Burq Rs 50 | D15: 48 | E15: =INT(C15/D15) | F15: =C15-(E15*D15) | H15: =C15*G15
A16: 11 | B16: Burq Rs 99 | D16: 24 | E16: =INT(C16/D16) | F16: =C16-(E16*D16) | H16: =C16*G16
A17: 12 | B17: Burq 1kg | D17: 12 | E17: =INT(C17/D17) | F17: =C17-(E17*D17) | H17: =C17*G17
... A39: 34 | B39: Tanga (C) | D39: 10 | E39: =INT(C39/D39) | F39: =C39-(E39*D39) | H39: =C39*G39
A40: TOTALS | E40: =SUM(E6:E39) | H40: =SUM(H6:H39)
A43: DAILY EXPENSES
A45: Category | B45: Amount (Rs)
A46: Labor | B46: 0
A47: Transport | B47: 0
A48: Utilities | B48: 0
A49: Packaging | B49: 0
A50: Other | B50: 0
A51: Total Expenses | B51: =SUM(B46:B50)

Sheet Day 28
A1: DAILY SALES & EXPENSES - DAY 28
A3: DAILY SALES ENTRY (Packs)
A5: SKU # | B5: SKU Name | C5: Packs Sold | D5: Units/Ctn | E5: Ctns | F5: Packs | G5: Rs/Pack | H5: Total Rs
A6: 1 | B6: Kite Rs 10 | D6: 144 | E6: =INT(C6/D6) | F6: =C6-(E6*D6) | H6: =C6*G6
A7: 2 | B7: Kite Rs 20 | D7: 96 | E7: =INT(C7/D7) | F7: =C7-(E7*D7) | H7: =C7*G7
A8: 3 | B8: Kite Rs 50 | D8: 48 | E8: =INT(C8/D8) | F8: =C8-(E8*D8) | H8: =C8*G8
A9: 4 | B9: Kite Rs 99 | D9: 24 | E9: =INT(C9/D9) | F9: =C9-(E9*D9) | H9: =C9*G9
A10: 5 | B10: Kite 0.5kg | D10: 24 | E10: =INT(C10/D10) | F10: =C10-(E10*D10) | H10: =C10*G10
A11: 6 | B11: Kite 1kg | D11: 12 | E11: =INT(C11/D11) | F11: =C11-(E11*D11) | H11: =C11*G11
A12: 7 | B12: Kite 2kg | D12: 6 | E12: =INT(C12/D12) | F12: =C12-(E12*D12) | H12: =C12*G12
A13: 8 | B13: Burq Rs 10 | D13: 204 | E13: =INT(C13/D13) | F13: =C13-(E13*D13) | H13: =C13*G13
A14: 9 | B14: Burq Rs 20 | D14: 96 | E14: =INT(C14/D14) | F14: =C14-(E14*D14) | H14: =C14*G14
A15: 10 | B15: Burq Rs 50 | D15: 48 | E15: =INT(C15/D15) | F15: =C15-(E15*D15) | H15: =C15*G15
A16: 11 | B16: Burq Rs 99 | D16: 24 | E16: =INT(C16/D16) | F16: =C16-(E16*D16) | H16: =C16*G16
A17: 12 | B17: Burq 1kg | D17: 12 | E17: =INT(C17/D17) | F17: =C17-(E17*D17) | H17: =C17*G17
... A39: 34 | B39: Tanga (C) | D39: 10 | E39: =INT(C39/D39) | F39: =C39-(E39*D39) | H39: =C39*G39
A40: TOTALS | E40: =SUM(E6:E39) | H40: =SUM(H6:H39)
A43: DAILY EXPENSES
A45: Category | B45: Amount (Rs)
A46: Labor | B46: 0
A47: Transport | B47: 0
A48: Utilities | B48: 0
A49: Packaging | B49: 0
A50: Other | B50: 0
A51: Total Expenses | B51: =SUM(B46:B50)

Sheet Day 29
A1: DAILY SALES & EXPENSES - DAY 29
A3: DAILY SALES ENTRY (Packs)
A5: SKU # | B5: SKU Name | C5: Packs Sold | D5: Units/Ctn | E5: Ctns | F5: Packs | G5: Rs/Pack | H5: Total Rs
A6: 1 | B6: Kite Rs 10 | D6: 144 | E6: =INT(C6/D6) | F6: =C6-(E6*D6) | H6: =C6*G6
A7: 2 | B7: Kite Rs 20 | D7: 96 | E7: =INT(C7/D7) | F7: =C7-(E7*D7) | H7: =C7*G7
A8: 3 | B8: Kite Rs 50 | D8: 48 | E8: =INT(C8/D8) | F8: =C8-(E8*D8) | H8: =C8*G8
A9: 4 | B9: Kite Rs 99 | D9: 24 | E9: =INT(C9/D9) | F9: =C9-(E9*D9) | H9: =C9*G9
A10: 5 | B10: Kite 0.5kg | D10: 24 | E10: =INT(C10/D10) | F10: =C10-(E10*D10) | H10: =C10*G10
A11: 6 | B11: Kite 1kg | D11: 12 | E11: =INT(C11/D11) | F11: =C11-(E11*D11) | H11: =C11*G11
A12: 7 | B12: Kite 2kg | D12: 6 | E12: =INT(C12/D12) | F12: =C12-(E12*D12) | H12: =C12*G12
A13: 8 | B13: Burq Rs 10 | D13: 204 | E13: =INT(C13/D13) | F13: =C13-(E13*D13) | H13: =C13*G13
A14: 9 | B14: Burq Rs 20 | D14: 96 | E14: =INT(C14/D14) | F14: =C14-(E14*D14) | H14: =C14*G14
A15: 10 | B15: Burq Rs 50 | D15: 48 | E15: =INT(C15/D15) | F15: =C15-(E15*D15) | H15: =C15*G15
A16: 11 | B16: Burq Rs 99 | D16: 24 | E16: =INT(C16/D16) | F16: =C16-(E16*D16) | H16: =C16*G16
A17: 12 | B17: Burq 1kg | D17: 12 | E17: =INT(C17/D17) | F17: =C17-(E17*D17) | H17: =C17*G17
... A39: 34 | B39: Tanga (C) | D39: 10 | E39: =INT(C39/D39) | F39: =C39-(E39*D39) | H39: =C39*G39
A40: TOTALS | E40: =SUM(E6:E39) | H40: =SUM(H6:H39)
A43: DAILY EXPENSES
A45: Category | B45: Amount (Rs)
A46: Labor | B46: 0
A47: Transport | B47: 0
A48: Utilities | B48: 0
A49: Packaging | B49: 0
A50: Other | B50: 0
A51: Total Expenses | B51: =SUM(B46:B50)

Sheet Day 30
A1: DAILY SALES & EXPENSES - DAY 30
A3: DAILY SALES ENTRY (Packs)
A5: SKU # | B5: SKU Name | C5: Packs Sold | D5: Units/Ctn | E5: Ctns | F5: Packs | G5: Rs/Pack | H5: Total Rs
A6: 1 | B6: Kite Rs 10 | D6: 144 | E6: =INT(C6/D6) | F6: =C6-(E6*D6) | H6: =C6*G6
A7: 2 | B7: Kite Rs 20 | D7: 96 | E7: =INT(C7/D7) | F7: =C7-(E7*D7) | H7: =C7*G7
A8: 3 | B8: Kite Rs 50 | D8: 48 | E8: =INT(C8/D8) | F8: =C8-(E8*D8) | H8: =C8*G8
A9: 4 | B9: Kite Rs 99 | D9: 24 | E9: =INT(C9/D9) | F9: =C9-(E9*D9) | H9: =C9*G9
A10: 5 | B10: Kite 0.5kg | D10: 24 | E10: =INT(C10/D10) | F10: =C10-(E10*D10) | H10: =C10*G10
A11: 6 | B11: Kite 1kg | D11: 12 | E11: =INT(C11/D11) | F11: =C11-(E11*D11) | H11: =C11*G11
A12: 7 | B12: Kite 2kg | D12: 6 | E12: =INT(C12/D12) | F12: =C12-(E12*D12) | H12: =C12*G12
A13: 8 | B13: Burq Rs 10 | D13: 204 | E13: =INT(C13/D13) | F13: =C13-(E13*D13) | H13: =C13*G13
A14: 9 | B14: Burq Rs 20 | D14: 96 | E14: =INT(C14/D14) | F14: =C14-(E14*D14) | H14: =C14*G14
A15: 10 | B15: Burq Rs 50 | D15: 48 | E15: =INT(C15/D15) | F15: =C15-(E15*D15) | H15: =C15*G15
A16: 11 | B16: Burq Rs 99 | D16: 24 | E16: =INT(C16/D16) | F16: =C16-(E16*D16) | H16: =C16*G16
A17: 12 | B17: Burq 1kg | D17: 12 | E17: =INT(C17/D17) | F17: =C17-(E17*D17) | H17: =C17*G17
... A39: 34 | B39: Tanga (C) | D39: 10 | E39: =INT(C39/D39) | F39: =C39-(E39*D39) | H39: =C39*G39
A40: TOTALS | E40: =SUM(E6:E39) | H40: =SUM(H6:H39)
A43: DAILY EXPENSES
A45: Category | B45: Amount (Rs)
A46: Labor | B46: 0
A47: Transport | B47: 0
A48: Utilities | B48: 0
A49: Packaging | B49: 0
A50: Other | B50: 0
A51: Total Expenses | B51: =SUM(B46:B50)

Sheet Day 31
A1: DAILY SALES & EXPENSES - DAY 31
A3: DAILY SALES ENTRY (Packs)
A5: SKU # | B5: SKU Name | C5: Packs Sold | D5: Units/Ctn | E5: Ctns | F5: Packs | G5: Rs/Pack | H5: Total Rs
A6: 1 | B6: Kite Rs 10 | D6: 144 | E6: =INT(C6/D6) | F6: =C6-(E6*D6) | H6: =C6*G6
A7: 2 | B7: Kite Rs 20 | D7: 96 | E7: =INT(C7/D7) | F7: =C7-(E7*D7) | H7: =C7*G7
A8: 3 | B8: Kite Rs 50 | D8: 48 | E8: =INT(C8/D8) | F8: =C8-(E8*D8) | H8: =C8*G8
A9: 4 | B9: Kite Rs 99 | D9: 24 | E9: =INT(C9/D9) | F9: =C9-(E9*D9) | H9: =C9*G9
A10: 5 | B10: Kite 0.5kg | D10: 24 | E10: =INT(C10/D10) | F10: =C10-(E10*D10) | H10: =C10*G10
A11: 6 | B11: Kite 1kg | D11: 12 | E11: =INT(C11/D11) | F11: =C11-(E11*D11) | H11: =C11*G11
A12: 7 | B12: Kite 2kg | D12: 6 | E12: =INT(C12/D12) | F12: =C12-(E12*D12) | H12: =C12*G12
A13: 8 | B13: Burq Rs 10 | D13: 204 | E13: =INT(C13/D13) | F13: =C13-(E13*D13) | H13: =C13*G13
A14: 9 | B14: Burq Rs 20 | D14: 96 | E14: =INT(C14/D14) | F14: =C14-(E14*D14) | H14: =C14*G14
A15: 10 | B15: Burq Rs 50 | D15: 48 | E15: =INT(C15/D15) | F15: =C15-(E15*D15) | H15: =C15*G15
A16: 11 | B16: Burq Rs 99 | D16: 24 | E16: =INT(C16/D16) | F16: =C16-(E16*D16) | H16: =C16*G16
A17: 12 | B17: Burq 1kg | D17: 12 | E17: =INT(C17/D17) | F17: =C17-(E17*D17) | H17: =C17*G17
... A39: 34 | B39: Tanga (C) | D39: 10 | E39: =INT(C39/D39) | F39: =C39-(E39*D39) | H39: =C39*G39
A40: TOTALS | E40: =SUM(E6:E39) | H40: =SUM(H6:H39)
A43: DAILY EXPENSES
A45: Category | B45: Amount (Rs)
A46: Labor | B46: 0
A47: Transport | B47: 0
A48: Utilities | B48: 0
A49: Packaging | B49: 0
A50: Other | B50: 0
A51: Total Expenses | B51: =SUM(B46:B50)

Sheet Secondary Sales Summary
A1: SECONDARY SALES SUMMARY (Auto-calculated from Daily)
A2: Automatically sums all daily sales from Day 1-31
A4: SKU # | B4: SKU Name | C4: Units/Ctn | D4: Total Packs | E4: Total Ctns | F4: Remaining Packs | G4: Total Ctns.Packs
A5: 1 | B5: Kite Rs 10 | C5: 144 | D5: ='Day 01'!C6+'Day 02'!C6+'Day 03'!C6+'Day 04'!C6+'Day 05'!C6+'Day 06'!C6+'Day 07'!C6+'Day 08'!C6+'Day 09'!C6+'Day 10'!C6+'Day 11'!C6+'Day 12'!C6+'Day 13'!C6+'Day 14'!C6+'Day 15'!C6+'Day 16'!C6+'Day 17'!C6+'Day 18'!C6+'Day 19'!C6+'Day 20'!C6+'Day 21'!C6+'Day 22'!C6+'Day 23'!C6+'Day 24'!C6+'Day 25'!C6+'Day 26'!C6+'Day 27'!C6+'Day 28'!C6+'Day 29'!C6+'Day 30'!C6+'Day 31'!C6 | E5: =INT(D5/C5) | F5: =D5-(E5*C5) | G5: =E5+F5/C5
A6: 2 | B6: Kite Rs 20 | C6: 96 | D6: ='Day 01'!C7+'Day 02'!C7+'Day 03'!C7+'Day 04'!C7+'Day 05'!C7+'Day 06'!C7+'Day 07'!C7+'Day 08'!C7+'Day 09'!C7+'Day 10'!C7+'Day 11'!C7+'Day 12'!C7+'Day 13'!C7+'Day 14'!C7+'Day 15'!C7+'Day 16'!C7+'Day 17'!C7+'Day 18'!C7+'Day 19'!C7+'Day 20'!C7+'Day 21'!C7+'Day 22'!C7+'Day 23'!C7+'Day 24'!C7+'Day 25'!C7+'Day 26'!C7+'Day 27'!C7+'Day 28'!C7+'Day 29'!C7+'Day 30'!C7+'Day 31'!C7 | E6: =INT(D6/C6) | F6: =D6-(E6*C6) | G6: =E6+F6/C6
A7: 3 | B7: Kite Rs 50 | C7: 48 | D7: ='Day 01'!C8+'Day 02'!C8+'Day 03'!C8+'Day 04'!C8+'Day 05'!C8+'Day 06'!C8+'Day 07'!C8+'Day 08'!C8+'Day 09'!C8+'Day 10'!C8+'Day 11'!C8+'Day 12'!C8+'Day 13'!C8+'Day 14'!C8+'Day 15'!C8+'Day 16'!C8+'Day 17'!C8+'Day 18'!C8+'Day 19'!C8+'Day 20'!C8+'Day 21'!C8+'Day 22'!C8+'Day 23'!C8+'Day 24'!C8+'Day 25'!C8+'Day 26'!C8+'Day 27'!C8+'Day 28'!C8+'Day 29'!C8+'Day 30'!C8+'Day 31'!C8 | E7: =INT(D7/C7) | F7: =D7-(E7*C7) | G7: =E7+F7/C7
A8: 4 | B8: Kite Rs 99 | C8: 24 | D8: ='Day 01'!C9+'Day 02'!C9+'Day 03'!C9+'Day 04'!C9+'Day 05'!C9+'Day 06'!C9+'Day 07'!C9+'Day 08'!C9+'Day 09'!C9+'Day 10'!C9+'Day 11'!C9+'Day 12'!C9+'Day 13'!C9+'Day 14'!C9+'Day 15'!C9+'Day 16'!C9+'Day 17'!C9+'Day 18'!C9+'Day 19'!C9+'Day 20'!C9+'Day 21'!C9+'Day 22'!C9+'Day 23'!C9+'Day 24'!C9+'Day 25'!C9+'Day 26'!C9+'Day 27'!C9+'Day 28'!C9+'Day 29'!C9+'Day 30'!C9+'Day 31'!C9 | E8: =INT(D8/C8) | F8: =D8-(E8*C8) | G8: =E8+F8/C8
A9: 5 | B9: Kite 0.5kg | C9: 24 | D9: ='Day 01'!C10+'Day 02'!C10+'Day 03'!C10+'Day 04'!C10+'Day 05'!C10+'Day 06'!C10+'Day 07'!C10+'Day 08'!C10+'Day 09'!C10+'Day 10'!C10+'Day 11'!C10+'Day 12'!C10+'Day 13'!C10+'Day 14'!C10+'Day 15'!C10+'Day 16'!C10+'Day 17'!C10+'Day 18'!C10+'Day 19'!C10+'Day 20'!C10+'Day 21'!C10+'Day 22'!C10+'Day 23'!C10+'Day 24'!C10+'Day 25'!C10+'Day 26'!C10+'Day 27'!C10+'Day 28'!C10+'Day 29'!C10+'Day 30'!C10+'Day 31'!C10 | E9: =INT(D9/C9) | F9: =D9-(E9*C9) | G9: =E9+F9/C9
A10: 6 | B10: Kite 1kg | C10: 12 | D10: ='Day 01'!C11+'Day 02'!C11+'Day 03'!C11+'Day 04'!C11+'Day 05'!C11+'Day 06'!C11+'Day 07'!C11+'Day 08'!C11+'Day 09'!C11+'Day 10'!C11+'Day 11'!C11+'Day 12'!C11+'Day 13'!C11+'Day 14'!C11+'Day 15'!C11+'Day 16'!C11+'Day 17'!C11+'Day 18'!C11+'Day 19'!C11+'Day 20'!C11+'Day 21'!C11+'Day 22'!C11+'Day 23'!C11+'Day 24'!C11+'Day 25'!C11+'Day 26'!C11+'Day 27'!C11+'Day 28'!C11+'Day 29'!C11+'Day 30'!C11+'Day 31'!C11 | E10: =INT(D10/C10) | F10: =D10-(E10*C10) | G10: =E10+F10/C10
A11: 7 | B11: Kite 2kg | C11: 6 | D11: ='Day 01'!C12+'Day 02'!C12+'Day 03'!C12+'Day 04'!C12+'Day 05'!C12+'Day 06'!C12+'Day 07'!C12+'Day 08'!C12+'Day 09'!C12+'Day 10'!C12+'Day 11'!C12+'Day 12'!C12+'Day 13'!C12+'Day 14'!C12+'Day 15'!C12+'Day 16'!C12+'Day 17'!C12+'Day 18'!C12+'Day 19'!C12+'Day 20'!C12+'Day 21'!C12+'Day 22'!C12+'Day 23'!C12+'Day 24'!C12+'Day 25'!C12+'Day 26'!C12+'Day 27'!C12+'Day 28'!C12+'Day 29'!C12+'Day 30'!C12+'Day 31'!C12 | E11: =INT(D11/C11) | F11: =D11-(E11*C11) | G11: =E11+F11/C11
A12: 8 | B12: Burq Rs 10 | C12: 204 | D12: ='Day 01'!C13+'Day 02'!C13+'Day 03'!C13+'Day 04'!C13+'Day 05'!C13+'Day 06'!C13+'Day 07'!C13+'Day 08'!C13+'Day 09'!C13+'Day 10'!C13+'Day 11'!C13+'Day 12'!C13+'Day 13'!C13+'Day 14'!C13+'Day 15'!C13+'Day 16'!C13+'Day 17'!C13+'Day 18'!C13+'Day 19'!C13+'Day 20'!C13+'Day 21'!C13+'Day 22'!C13+'Day 23'!C13+'Day 24'!C13+'Day 25'!C13+'Day 26'!C13+'Day 27'!C13+'Day 28'!C13+'Day 29'!C13+'Day 30'!C13+'Day 31'!C13 | E12: =INT(D12/C12) | F12: =D12-(E12*C12) | G12: =E12+F12/C12
A13: 9 | B13: Burq Rs 20 | C13: 96 | D13: ='Day 01'!C14+'Day 02'!C14+'Day 03'!C14+'Day 04'!C14+'Day 05'!C14+'Day 06'!C14+'Day 07'!C14+'Day 08'!C14+'Day 09'!C14+'Day 10'!C14+'Day 11'!C14+'Day 12'!C14+'Day 13'!C14+'Day 14'!C14+'Day 15'!C14+'Day 16'!C14+'Day 17'!C14+'Day 18'!C14+'Day 19'!C14+'Day 20'!C14+'Day 21'!C14+'Day 22'!C14+'Day 23'!C14+'Day 24'!C14+'Day 25'!C14+'Day 26'!C14+'Day 27'!C14+'Day 28'!C14+'Day 29'!C14+'Day 30'!C14+'Day 31'!C14 | E13: =INT(D13/C13) | F13: =D13-(E13*C13) | G13: =E13+F13/C13
A14: 10 | B14: Burq Rs 50 | C14: 48 | D14: ='Day 01'!C15+'Day 02'!C15+'Day 03'!C15+'Day 04'!C15+'Day 05'!C15+'Day 06'!C15+'Day 07'!C15+'Day 08'!C15+'Day 09'!C15+'Day 10'!C15+'Day 11'!C15+'Day 12'!C15+'Day 13'!C15+'Day 14'!C15+'Day 15'!C15+'Day 16'!C15+'Day 17'!C15+'Day 18'!C15+'Day 19'!C15+'Day 20'!C15+'Day 21'!C15+'Day 22'!C15+'Day 23'!C15+'Day 24'!C15+'Day 25'!C15+'Day 26'!C15+'Day 27'!C15+'Day 28'!C15+'Day 29'!C15+'Day 30'!C15+'Day 31'!C15 | E14: =INT(D14/C14) | F14: =D14-(E14*C14) | G14: =E14+F14/C14
A15: 11 | B15: Burq Rs 99 | C15: 24 | D15: ='Day 01'!C16+'Day 02'!C16+'Day 03'!C16+'Day 04'!C16+'Day 05'!C16+'Day 06'!C16+'Day 07'!C16+'Day 08'!C16+'Day 09'!C16+'Day 10'!C16+'Day 11'!C16+'Day 12'!C16+'Day 13'!C16+'Day 14'!C16+'Day 15'!C16+'Day 16'!C16+'Day 17'!C16+'Day 18'!C16+'Day 19'!C16+'Day 20'!C16+'Day 21'!C16+'Day 22'!C16+'Day 23'!C16+'Day 24'!C16+'Day 25'!C16+'Day 26'!C16+'Day 27'!C16+'Day 28'!C16+'Day 29'!C16+'Day 30'!C16+'Day 31'!C16 | E15: =INT(D15/C15) | F15: =D15-(E15*C15) | G15: =E15+F15/C15
A16: 12 | B16: Burq 1kg | C16: 12 | D16: ='Day 01'!C17+'Day 02'!C17+'Day 03'!C17+'Day 04'!C17+'Day 05'!C17+'Day 06'!C17+'Day 07'!C17+'Day 08'!C17+'Day 09'!C17+'Day 10'!C17+'Day 11'!C17+'Day 12'!C17+'Day 13'!C17+'Day 14'!C17+'Day 15'!C17+'Day 16'!C17+'Day 17'!C17+'Day 18'!C17+'Day 19'!C17+'Day 20'!C17+'Day 21'!C17+'Day 22'!C17+'Day 23'!C17+'Day 24'!C17+'Day 25'!C17+'Day 26'!C17+'Day 27'!C17+'Day 28'!C17+'Day 29'!C17+'Day 30'!C17+'Day 31'!C17 | E16: =INT(D16/C16) | F16: =D16-(E16*C16) | G16: =E16+F16/C16
... A38: 34 | B38: Tanga (C) | C38: 10 | D38: ='Day 01'!C39+'Day 02'!C39+'Day 03'!C39+'Day 04'!C39+'Day 05'!C39+'Day 06'!C39+'Day 07'!C39+'Day 08'!C39+'Day 09'!C39+'Day 10'!C39+'Day 11'!C39+'Day 12'!C39+'Day 13'!C39+'Day 14'!C39+'Day 15'!C39+'Day 16'!C39+'Day 17'!C39+'Day 18'!C39+'Day 19'!C39+'Day 20'!C39+'Day 21'!C39+'Day 22'!C39+'Day 23'!C39+'Day 24'!C39+'Day 25'!C39+'Day 26'!C39+'Day 27'!C39+'Day 28'!C39+'Day 29'!C39+'Day 30'!C39+'Day 31'!C39 | E38: =INT(D38/C38) | F38: =D38-(E38*C38) | G38: =E38+F38/C38

Sheet Primary Sales Summary
A1: PRIMARY SALES SUMMARY (Auto-calculated)
A4: SKU # | B4: SKU Name | C4: Units/Ctn | D4: Total Primary (Ctns) | E4: Total Amount (Rs)
A5: 1 | B5: Kite Rs 10 | C5: 144 | D5: =SUMIF('Primary Sales Entry'!B:B,A5,'Primary Sales Entry'!E:E) | E5: =SUMIF('Primary Sales Entry'!B:B,A5,'Primary Sales Entry'!F:F)
A6: 2 | B6: Kite Rs 20 | C6: 96 | D6: =SUMIF('Primary Sales Entry'!B:B,A6,'Primary Sales Entry'!E:E) | E6: =SUMIF('Primary Sales Entry'!B:B,A6,'Primary Sales Entry'!F:F)
A7: 3 | B7: Kite Rs 50 | C7: 48 | D7: =SUMIF('Primary Sales Entry'!B:B,A7,'Primary Sales Entry'!E:E) | E7: =SUMIF('Primary Sales Entry'!B:B,A7,'Primary Sales Entry'!F:F)
A8: 4 | B8: Kite Rs 99 | C8: 24 | D8: =SUMIF('Primary Sales Entry'!B:B,A8,'Primary Sales Entry'!E:E) | E8: =SUMIF('Primary Sales Entry'!B:B,A8,'Primary Sales Entry'!F:F)
A9: 5 | B9: Kite 0.5kg | C9: 24 | D9: =SUMIF('Primary Sales Entry'!B:B,A9,'Primary Sales Entry'!E:E) | E9: =SUMIF('Primary Sales Entry'!B:B,A9,'Primary Sales Entry'!F:F)
A10: 6 | B10: Kite 1kg | C10: 12 | D10: =SUMIF('Primary Sales Entry'!B:B,A10,'Primary Sales Entry'!E:E) | E10: =SUMIF('Primary Sales Entry'!B:B,A10,'Primary Sales Entry'!F:F)
